Workbook

Sheet Info
A1: Work Order: | H1: =Switches!AK2 -> 0 | I1: =Switches!AL2 -> 0 | J1: Gage Blocks | M1: =Switches!AM2 -> 0 | N1: =Switches!AN2 -> 0 | O1: =Switches!AO2 -> 0 | P1: =Switches!AP2 -> 0 | Q1: =Switches!AQ2 -> 0 | AA1: ISO Length Recommendation Table
A2: Customer: | H2: =IF(Switches!BD3=2,ROUNDUP(B16*0.25,0),IF(Switches!BD3=3,ROUNDUP(B16*0.25,0),"N/A")) -> N/A | I2: =IF(Switches!BD3=3,ROUNDUP(B16*0.6,0),"N/A") -> N/A | J2: Size | K2: S/N | L2: Set | M2: =IF(Switches!$BD3=4,AB2,"N/A") -> N/A | N2: =IF(Switches!$BD3=4,AC2,"N/A") -> N/A | O2: =IF(Switches!$BD3=4,AD2,"N/A") -> N/A | P2: =IF(Switches!$BD3=4,AE2,"N/A") -> N/A | Q2: =IF(Switches!$BD3=4,AF2,"N/A") -> N/A | AA2: =B16 -> #N/A | AB2: =VLOOKUP(AA2,AA3:AF201,2,FALSE) -> #N/A | AC2: =VLOOKUP(AA2,AA3:AF201,3,FALSE) -> #N/A | AD2: =VLOOKUP(AA2,AA3:AF201,4,FALSE) -> #N/A | AE2: =VLOOKUP(AA2,AA3:AF201,5,FALSE) -> #N/A | AF2: =VLOOKUP(AA2,AA3:AF201,6,FALSE) -> #N/A
A3: Address Line 1: | B3: [Optional - does not appear on data sheets] | J3: =Standards!C23 -> 1 | K3: =Standards!B23 -> 99811 | L3: =Standards!I23 -> Set 6 | AA3: 12 | AB3: 1 | AC3: 2 | AD3: 4 | AE3: 6 | AF3: 8
A4: Address Line 2: | B4: [Optional - does not appear on data sheets] | J4: =Standards!C24 -> 2 | K4: =Standards!B24 -> 12077 | L4: =Standards!I24 -> Set 6 | AA4: =AA3+1 -> 13 | AB4: =AB5 -> 2 | AC4: =AC5 -> 4 | AD4: =AD5 -> 6 | AE4: =AE5 -> 8 | AF4: =AF5 -> 10
A5: Date Tested: | C5: Date Due: | D5: =DATE(YEAR(B5)+Switches!V4,MONTH(B5)+Switches!V3,DAY(B5)) -> 366 | J5: =Standards!C25 -> 3 | K5: =Standards!B25 -> F621 | L5: =Standards!I25 -> Set 6 | AA5: =AA4+1 -> 14 | AB5: =AB6 -> 2 | AC5: =AC6 -> 4 | AD5: =AD6 -> 6 | AE5: =AE6 -> 8 | AF5: =AF6 -> 10
A6: Inspector: | F6: Set 6 | J6: =Standards!C26 -> 4 | K6: =Standards!B26 -> ML-1B | L6: =Standards!I26 -> Set 6 | AA6: 15 | AB6: 2 | AC6: 4 | AD6: 6 | AE6: 8 | AF6: 10
A7: Location: | F7: =IF(AND(Switches!AI37=TRUE,Switches!AK37=TRUE),"Past Due!",IF(Switches!AI37=TRUE,"Active","N/A")) -> N/A | J7: =Standards!C27 -> 8 | K7: =Standards!B27 -> 13015 | L7: =Standards!I27 -> Set 6 | AA7: =AA6+1 -> 16 | AB7: =AB8 -> 4 | AC7: =AC8 -> 6 | AD7: =AD8 -> 8 | AE7: =AE8 -> 10 | AF7: =AF8 -> 12
A8: Serial Number: | J8: =Standards!C28 -> 12 | K8: =Standards!B28 -> 12002 | L8: =Standards!I28 -> Set 6 | AA8: =AA7+1 -> 17 | AB8: =AB9 -> 4 | AC8: =AC9 -> 6 | AD8: =AD9 -> 8 | AE8: =AE9 -> 10 | AF8: =AF9 -> 12
A9: Unit Number: | J9: =Standards!C29 -> 16 | K9: =Standards!B29 -> C259 | L9: =Standards!I29 -> Set 6 | AA9: 18 | AB9: 4 | AC9: 6 | AD9: 8 | AE9: 10 | AF9: 12
A10: Resolution: | B10: 1e-05 | J10: =Standards!C30 -> 20 | K10: =Standards!B30 -> 23023 | L10: =Standards!I30 -> Set 6 | AA10: =AA9+1 -> 19 | AB10: =AB11 -> 4 | AC10: =AC11 -> 6 | AD10: =AD11 -> 10 | AE10: =AE11 -> 12 | AF10: =AF11 -> 16
A11: Software: | B11: [Optional] | J11: =Standards!C2 -> 1 | K11: =Standards!B2 -> 15026 | L11: =Standards!I2 -> Set 11 | AA11: =AA10+1 -> 20 | AB11: =AB12 -> 4 | AC11: =AC12 -> 6 | AD11: =AD12 -> 10 | AE11: =AE12 -> 12 | AF11: =AF12 -> 16
A12: Software Version: | B12: [Optional] | C12: Machine information can be input manually if it is not in the database | J12: =Standards!C3 -> 2 | K12: =Standards!B3 -> 92278 | L12: =Standards!I3 -> Set 11 | AA12: =AA11+1 -> 21 | AB12: =AB13 -> 4 | AC12: =AC13 -> 6 | AD12: =AD13 -> 10 | AE12: =AE13 -> 12 | AF12: =AF13 -> 16
A13: Manufacturer | B13: =VLOOKUP(Switches!$G$2,Table1[[ID'#]:[End]],9,FALSE) -> #N/A | F13: =Switches!G2 -> 10101 | J13: =Standards!C4 -> 4 | K13: =Standards!B4 -> 87159 | L13: =Standards!I4 -> Set 11 | AA13: =AA12+1 -> 22 | AB13: =AB14 -> 4 | AC13: =AC14 -> 6 | AD13: =AD14 -> 10 | AE13: =AE14 -> 12 | AF13: =AF14 -> 16
A14: Model: | B14: =VLOOKUP(Switches!$G$2,Table1[[ID'#]:[End]],7,FALSE) -> #N/A | D14: =B13&" "&B14 -> #N/A | J14: =Standards!C5 -> 5 | K14: =Standards!B5 -> 97087 | L14: =Standards!I5 -> Set 11 | AA14: =AA13+1 -> 23 | AB14: =AB15 -> 4 | AC14: =AC15 -> 6 | AD14: =AD15 -> 10 | AE14: =AE15 -> 12 | AF14: =AF15 -> 16
A15: Number of Axes: | B15: =VLOOKUP(Switches!$G$2,Table1[[ID'#]:[End]],12,FALSE) -> #N/A | D15: =IF(AND(Switches!A2=2,Switches!C2=11),"Check machine for additional tolerances for Quantum X.","") | F15: Set 11 | J15: =Standards!C6 -> 6 | K15: =Standards!B6 -> 96002 | L15: =Standards!I6 -> Set 11 | AA15: 24 | AB15: 4 | AC15: 6 | AD15: 10 | AE15: 12 | AF15: 16
A16: Measuring Range (in): | B16: =VLOOKUP(Switches!$G$2,Table1[[ID'#]:[End]],10,FALSE) -> #N/A | C16: Tolerance can be entered manually | F16: =IF(AND(Switches!AI38=TRUE,Switches!AK38=TRUE),"Past Due!",IF(Switches!AI38=TRUE,"Active","N/A")) -> N/A | J16: =Standards!C7 -> 7 | K16: =Standards!B7 -> 2305 | L16: =Standards!I7 -> Set 11 | AA16: =AA15+1 -> 25 | AB16: =AB17 -> 4 | AC16: =AC17 -> 8 | AD16: =AD17 -> 12 | AE16: =AE17 -> 16 | AF16: =AF17 -> 20
A17: Tolerance Source | C17: (Inch/mm) | D17: Results | G17: =IF(Switches!BD3=3,"Make sure we bill for ASME method!",IF(Switches!BD3=4,"Are you sure you want to use ISO?","")) | J17: =Standards!C8 -> 8 | K17: =Standards!B8 -> 13013 | L17: =Standards!I8 -> Set 11 | AA17: =AA16+1 -> 26 | AB17: =AB18 -> 4 | AC17: =AC18 -> 8 | AD17: =AD18 -> 12 | AE17: =AE18 -> 16 | AF17: =AF18 -> 20
A18: SPAT | C18: =Switches!I5 -> #N/A | D18: =IF(Switches!BC3=3,MAX(SPAT1!N22,SPAT2!N22,SPAT3!N22),SPAT1!N22) -> 0 | E18: Specified Method | F18: =VLOOKUP(Switches!$G$2,Table1[[ID'#]:[End]],23,FALSE) -> #N/A | G18: =IF(Switches!AA3=0,"OK","!") -> #N/A | J18: =Standards!C9 -> 10 | K18: =Standards!B9 -> 08179 | L18: =Standards!I9 -> Set 11 | AA18: =AA17+1 -> 27 | AB18: =AB19 -> 4 | AC18: =AC19 -> 8 | AD18: =AD19 -> 12 | AE18: =AE19 -> 16 | AF18: =AF19 -> 20
A19: Length/VPT/Euni: | C19: =Switches!J5 -> #N/A | D19: =IF(Switches!BD3=2,Length!S12,IF(Switches!BD3=3,'VPT (ASME)'!P4,IF(Switches!BD3=4,'Euni (ISO)'!L3,0))) -> 0 | E19: Specified Method | F19: =VLOOKUP(Switches!$G$2,Table1[[ID'#]:[End]],24,FALSE) -> #N/A | G19: =IF(Switches!AC3=0,"OK","!") -> #N/A | J19: =Standards!C10 -> 12 | K19: =Standards!B10 -> 1807 | L19: =Standards!I10 -> Set 11 | AA19: =AA18+1 -> 28 | AB19: =AB20 -> 4 | AC19: =AC20 -> 8 | AD19: =AD20 -> 12 | AE19: =AE20 -> 16 | AF19: =AF20 -> 20
A20: Psize | C20: =Switches!K5 -> #N/A | D20: =Probing!C20 -> #N/A | J20: =Standards!C11 -> 16 | K20: =Standards!B11 -> 1515 | L20: =Standards!I11 -> Set 11 | AA20: =AA19+1 -> 29 | AB20: =AB21 -> 4 | AC20: =AC21 -> 8 | AD20: =AD21 -> 12 | AE20: =AE21 -> 16 | AF20: =AF21 -> 20
A21: Pform | C21: =Switches!L5 -> #N/A | D21: =Probing!C21 -> 0 | J21: =Standards!C12 -> 20 | K21: =Standards!B12 -> 13002 | L21: =Standards!I12 -> Set 11 | AA21: 30 | AB21: 4 | AC21: 8 | AD21: 12 | AE21: 16 | AF21: 20
A22: LDIA | C22: =Switches!M5 -> #N/A | D22: ='Articulated Location'!D14 -> 0 | E22: Specified Method | F22: =VLOOKUP(Switches!$G$2,Table1[[ID'#]:[End]],25,FALSE) -> #N/A | G22: =IF(Switches!AE3=0,"OK","!") -> #N/A | J22: =Standards!C33 -> 1 | K22: =Standards!B33 -> 16191 | L22: =Standards!I33 -> Set 8 | AA22: =AA21+1 -> 31 | AB22: =AB23 -> 4 | AC22: =AC23 -> 8 | AD22: =AD23 -> 12 | AE22: =AE23 -> 16 | AF22: =AF23 -> 22
A23: EDPT | C23: =Switches!N5 -> Capability | D23: =EDPT!F10 -> #N/A | J23: =Standards!C34 -> 2 | K23: =Standards!B34 -> 98537 | L23: =Standards!I34 -> Set 8 | AA23: =AA22+1 -> 32 | AB23: =AB24 -> 4 | AC23: =AC24 -> 8 | AD23: =AD24 -> 12 | AE23: =AE24 -> 16 | AF23: =AF24 -> 22
A24: LLP attached to arm | J24: =Standards!C35 -> 3 | K24: =Standards!B35 -> 98588 | L24: =Standards!I35 -> Set 8 | AA24: 33 | AB24: 4 | AC24: 8 | AD24: 12 | AE24: 16 | AF24: 22
A25: Work Order: | F25: Set 8 | J25: =Standards!C36 -> 4 | K25: =Standards!B36 -> 98262 | L25: =Standards!I36 -> Set 8 | AA25: =AA24+1 -> 34 | AB25: =AB26 -> 6 | AC25: =AC26 -> 10 | AD25: =AD26 -> 16 | AE25: =AE26 -> 20 | AF25: =AF26 -> 24
A26: Serial Number: | F26: =IF(AND(Switches!AI39=TRUE,Switches!AK39=TRUE),"Past Due!",IF(Switches!AI39=TRUE,"Active","N/A")) -> N/A | J26: =Standards!C37 -> 5 | K26: =Standards!B37 -> 96030 | L26: =Standards!I37 -> Set 8 | AA26: =AA25+1 -> 35 | AB26: =AB27 -> 6 | AC26: =AC27 -> 10 | AD26: =AD27 -> 16 | AE26: =AE27 -> 20 | AF26: =AF27 -> 24
A27: Unit Number: | J27: =Standards!C38 -> 6 | K27: =Standards!B38 -> 17015 | L27: =Standards!I38 -> Set 8 | AA27: 36 | AB27: 6 | AC27: 10 | AD27: 16 | AE27: 20 | AF27: 24
A28: Manufacturer | B28: =IF(Switches!BV1=1,"",B13) | J28: =Standards!C39 -> 8 | K28: =Standards!B39 -> 13099 | L28: =Standards!I39 -> Set 8 | AA28: =AA27+1 -> 37 | AB28: =AB29 -> 6 | AC28: =AC29 -> 10 | AD28: =AD29 -> 16 | AE28: =AE29 -> 20 | AF28: =AF29 -> 26
A29: Model: | B29: =Switches!BW2 | D29: =B28&" "&B29 | J29: =Standards!C40 -> 10 | K29: =Standards!B40 -> 15002 | L29: =Standards!I40 -> Set 8 | AA29: =AA28+1 -> 38 | AB29: =AB30 -> 6 | AC29: =AC30 -> 10 | AD29: =AD30 -> 16 | AE29: =AE30 -> 20 | AF29: =AF30 -> 26
A30: Tolerance Source | C30: (Inch/mm) | D30: Results | J30: =Standards!C41 -> 12 | K30: =Standards!B41 -> 98081 | L30: =Standards!I41 -> Set 8 | AA30: 39 | AB30: 6 | AC30: 10 | AD30: 16 | AE30: 20 | AF30: 26
A31: SPAT | C31: =Switches!BW4 -> N/A | D31: =LLP!D14 -> 0 | E31: Specified Method | F31: =Switches!BW3 | G31: =IF(Switches!AA6=0,"OK","!") -> OK | J31: =Standards!C13 -> 1 | K31: =Standards!B13 -> R712B | L31: =Standards!I13 -> Set 12 | AA31: =AA30+1 -> 40 | AB31: =AB32 -> 6 | AC31: =AC32 -> 10 | AD31: =AD32 -> 16 | AE31: =AE32 -> 22 | AF31: =AF32 -> 28
A32: 8th-Axis attached to arm | J32: =Standards!C14 -> 2 | K32: =Standards!B14 -> 99900 | L32: =Standards!I14 -> Set 12 | AA32: =AA31+1 -> 41 | AB32: =AB33 -> 6 | AC32: =AC33 -> 10 | AD32: =AD33 -> 16 | AE32: =AE33 -> 22 | AF32: =AF33 -> 28
A33: Work Order: | F33: Set 12 | J33: =Standards!C15 -> 3 | K33: =Standards!B15 -> 03301 | L33: =Standards!I15 -> Set 12 | AA33: 42 | AB33: 6 | AC33: 10 | AD33: 16 | AE33: 22 | AF33: 28
A34: Serial Number: | F34: =IF(AND(Switches!AI40=TRUE,Switches!AK40=TRUE),"Past Due!",IF(Switches!AI40=TRUE,"Active","N/A")) -> N/A | J34: =Standards!C16 -> 4 | K34: =Standards!B16 -> 03327 | L34: =Standards!I16 -> Set 12 | AA34: =AA33+1 -> 43 | AB34: =AB35 -> 6 | AC34: =AC35 -> 12 | AD34: =AD35 -> 18 | AE34: =AE35 -> 24 | AF34: =AF35 -> 30
A35: Unit Number: | AA35: =AA34+1 -> 44 | AB35: =AB36 -> 6 | AC35: =AC36 -> 12 | AD35: =AD36 -> 18 | AE35: =AE36 -> 24 | AF35: =AF36 -> 30
A36: Manufacturer | B36: =IF(Switches!CK1=1,"",B13) | AA36: 45 | AB36: 6 | AC36: 12 | AD36: 18 | AE36: 24 | AF36: 30
A37: Model: | B37: =Switches!CL2 | D37: =B36&" "&B37 | AA37: =AA36+1 -> 46 | AB37: =AB38 -> 6 | AC37: =AC38 -> 12 | AD37: =AD38 -> 18 | AE37: =AE38 -> 24 | AF37: =AF38 -> 32
A38: Tolerance Source | C38: (Inch/mm) | D38: Results | AA38: =AA37+1 -> 47 | AB38: =AB39 -> 6 | AC38: =AC39 -> 12 | AD38: =AD39 -> 18 | AE38: =AE39 -> 24 | AF38: =AF39 -> 32
A39: LDIA | C39: =Switches!CL4 -> N/A | D39: ='8-Axis'!D14 -> 0 | E39: Specified Method | F39: =Switches!CL3 | G39: =IF(Switches!AE6=0,"OK","!") -> OK | AA39: 48 | AB39: 6 | AC39: 12 | AD39: 18 | AE39: 24 | AF39: 32
AA40: =AA39+1 -> 49 | AB40: =AB41 -> 6 | AC40: =AC41 -> 12 | AD40: =AD41 -> 20 | AE40: =AE41 -> 26 | AF40: =AF41 -> 34
...

Sheet Qualer
A1: Report | B1: =Info!B1 -> 0 | E1: AACMM | H1: Attributes
A2: Item | B2: =Info!D14 -> #N/A | H2: Condition: | I2: Used
A3: Date | B3: =Info!B5 -> 0 | C3: =Info!G17 | H3: Display Resolution: | I3: =Info!B10&"""" -> 0.00001"
A4: Pages | B4: =Switches!BI8 -> 1 | H4: Measuring Range: | I4: =Info!B16&"""" -> #N/A
A5: Temp | B5: =AVERAGE(G9,G11,G14,G17,G19,G21,G22) -> #DIV/0! | H5: Tolerance Source: | I5: =IF(Switches!U2=1,Switches!U3,Switches!U4) -> Manufacturer
A6: %RH | B6: =AVERAGE(H9,H11,H14,H17,H19,H21,H22) -> #DIV/0! | H6: Work Procedure: | I6: WP251895
B8: Test | C8: Tolerance | D8: Result | E8: Uncertainty | F8: Standard | G8: Temp | H8: RH | AB8: Test | AC8: Tolerance | AD8: Result | AE8: Uncertainty | AF8: Standard | AG8: Temp | AH8: RH
B9: =IF(Switches!BD3>1,Qualer!AB9,"") | C9: =IF(Switches!BD3>1,Qualer!AC9,"") | D9: =IF(Switches!BD3>1,Qualer!AD9,"") | E9: =IF(Switches!BD3>1,Qualer!AE9,"") | F9: =IF(Switches!BD3>1,Qualer!AF9,"") | G9: =IF(Switches!BD3>1,Qualer!AG9,"") | H9: =IF(Switches!BD3>1,Qualer!AH9,"") | AB9: Length | AC9: =Switches!J4 -> #N/A | AD9: =IF(Switches!BD3=2,Length!S12,IF(Switches!BD3=3,'VPT (ASME)'!P4,IF(Switches!BD3=4,'Euni (ISO)'!L3,0))) -> 0 | AE9: =ROUND(170+0.18*Info!B16/2,0) -> #N/A | AF9: =Switches!AH42 -> N/A | AG9: =IF(Switches!BD3=2,Switches!BD26,IF(Switches!BD3=3,Switches!BD28,IF(Switches!BD3=4,Switches!BD30,0))) -> 0 | AH9: =IF(Switches!BD3=2,Switches!BD27,IF(Switches!BD3=3,Switches!BD29,IF(Switches!BD3=4,Switches!BD31,0))) -> 0
B10: =IF(Switches!BC3>1,Qualer!AB10,"") | C10: =IF(Switches!BC3>1,Qualer!AC10,"") | D10: =IF(Switches!BC3>1,Qualer!AD10,"") | E10: =IF(Switches!BC3>1,Qualer!AE10,"") | F10: =IF(Switches!BC3>1,Qualer!AF10,"") | G10: =IF(Switches!BC3>1,Qualer!AG10,"") | H10: =IF(Switches!BC3>1,Qualer!AH10,"") | AB10: =IF(Switches!AA2=1,"SPAT-1-X","") -> SPAT-1-X | AC10: =IF(Switches!AA2=1,AC11,"") -> #N/A | AD10: =IF(Switches!AA2=1,Switches!BC17,"") -> 0 | AE10: =IF(Switches!AA2=1,AE11,"") -> 90 | AF10: =IF(Switches!AA2=1,AF11,"") -> N/A | AG10: =IF(Switches!AA2=1,AG11,"") -> 0 | AH10: =IF(Switches!AA2=1,AH11,"") -> 0
B11: =IF(Switches!BC3>1,Qualer!AB11,"") | C11: =IF(Switches!BC3>1,Qualer!AC11,"") | D11: =IF(Switches!BC3>1,Qualer!AD11,"") | E11: =IF(Switches!BC3>1,Qualer!AE11,"") | F11: =IF(Switches!BC3>1,Qualer!AF11,"") | G11: =IF(Switches!BC3>1,Qualer!AG11,"") | H11: =IF(Switches!BC3>1,Qualer!AH11,"") | AB11: =IF(Switches!AA2=1,"SPAT-1-Y","SPAT-1") -> SPAT-1-Y | AC11: =Switches!I4 -> #N/A | AD11: =IF(Switches!AA2=1,Switches!BC18,Switches!BC20) -> 0 | AE11: 90 | AF11: N/A | AG11: =SPAT1!L4 -> 0 | AH11: =SPAT1!L5 -> 0
B12: =IF(Switches!BC3>1,Qualer!AB12,"") | C12: =IF(Switches!BC3>1,Qualer!AC12,"") | D12: =IF(Switches!BC3>1,Qualer!AD12,"") | E12: =IF(Switches!BC3>1,Qualer!AE12,"") | F12: =IF(Switches!BC3>1,Qualer!AF12,"") | G12: =IF(Switches!BC3>1,Qualer!AG12,"") | H12: =IF(Switches!BC3>1,Qualer!AH12,"") | AB12: =IF(Switches!AA2=1,"SPAT-1-Z","") -> SPAT-1-Z | AC12: =AC10 -> #N/A | AD12: =IF(Switches!AA2=1,Switches!BC19,"") -> 0 | AE12: =AE10 -> 90 | AF12: =AF10 -> N/A | AG12: =AG10 -> 0 | AH12: =AH10 -> 0
B13: =IF(Switches!BC3>2,Qualer!AB13,"") | C13: =IF(Switches!BC3>2,Qualer!AC13,"") | D13: =IF(Switches!BC3>2,Qualer!AD13,"") | E13: =IF(Switches!BC3>2,Qualer!AE13,"") | F13: =IF(Switches!BC3>2,Qualer!AF13,"") | G13: =IF(Switches!BC3>2,Qualer!AG13,"") | H13: =IF(Switches!BC3>2,Qualer!AH13,"") | AB13: =IF(Switches!AA2=1,"SPAT-2-X","") -> SPAT-2-X | AC13: =IF(Switches!AA2=1,AC14,"") -> #N/A | AD13: =IF(Switches!AA2=1,Switches!BC21,"") -> 0 | AE13: =IF(Switches!AA2=1,AE14,"") -> 90 | AF13: =IF(Switches!AA2=1,AF14,"") -> N/A | AG13: =IF(Switches!AA2=1,AG14,"") -> 0 | AH13: =IF(Switches!AA2=1,AH14,"") -> 0
B14: =IF(Switches!BC3>2,Qualer!AB14,"") | C14: =IF(Switches!BC3>2,Qualer!AC14,"") | D14: =IF(Switches!BC3>2,Qualer!AD14,"") | E14: =IF(Switches!BC3>2,Qualer!AE14,"") | F14: =IF(Switches!BC3>2,Qualer!AF14,"") | G14: =IF(Switches!BC3>2,Qualer!AG14,"") | H14: =IF(Switches!BC3>2,Qualer!AH14,"") | AB14: =IF(Switches!AA2=1,"SPAT-2-Y","SPAT-2") -> SPAT-2-Y | AC14: =Switches!I4 -> #N/A | AD14: =IF(Switches!AA2=1,Switches!BC22,Switches!BC24) -> 0 | AE14: 90 | AF14: N/A | AG14: =SPAT2!L4 -> 0 | AH14: =SPAT2!L5 -> 0
B15: =IF(Switches!BC3>2,Qualer!AB15,"") | C15: =IF(Switches!BC3>2,Qualer!AC15,"") | D15: =IF(Switches!BC3>2,Qualer!AD15,"") | E15: =IF(Switches!BC3>2,Qualer!AE15,"") | F15: =IF(Switches!BC3>2,Qualer!AF15,"") | G15: =IF(Switches!BC3>2,Qualer!AG15,"") | H15: =IF(Switches!BC3>2,Qualer!AH15,"") | AB15: =IF(Switches!AA2=1,"SPAT-2-Z","") -> SPAT-2-Z | AC15: =AC13 -> #N/A | AD15: =IF(Switches!AA2=1,Switches!BC23,"") -> 0 | AE15: =AE13 -> 90 | AF15: =AF13 -> N/A | AG15: =AG13 -> 0 | AH15: =AH13 -> 0
B16: =IF(Switches!BC3>2,Qualer!AB16,"") | C16: =IF(Switches!BC3>2,Qualer!AC16,"") | D16: =IF(Switches!BC3>2,Qualer!AD16,"") | E16: =IF(Switches!BC3>2,Qualer!AE16,"") | F16: =IF(Switches!BC3>2,Qualer!AF16,"") | G16: =IF(Switches!BC3>2,Qualer!AG16,"") | H16: =IF(Switches!BC3>2,Qualer!AH16,"") | AB16: =IF(Switches!AA2=1,"SPAT-3-X","") -> SPAT-3-X | AC16: =IF(Switches!AA2=1,AC17,"") -> #N/A | AD16: =IF(Switches!AA2=1,Switches!BC25,"") -> 0 | AE16: =IF(Switches!AA2=1,AE17,"") -> 90 | AF16: =IF(Switches!AA2=1,AF17,"") -> N/A | AG16: =IF(Switches!AA2=1,AG17,"") -> 0 | AH16: =IF(Switches!AA2=1,AH17,"") -> 0
B17: =IF(Switches!BC3>2,Qualer!AB17,"") | C17: =IF(Switches!BC3>2,Qualer!AC17,"") | D17: =IF(Switches!BC3>2,Qualer!AD17,"") | E17: =IF(Switches!BC3>2,Qualer!AE17,"") | F17: =IF(Switches!BC3>2,Qualer!AF17,"") | G17: =IF(Switches!BC3>2,Qualer!AG17,"") | H17: =IF(Switches!BC3>2,Qualer!AH17,"") | AB17: =IF(Switches!AA2=1,"SPAT-3-Y","SPAT-3") -> SPAT-3-Y | AC17: =Switches!I4 -> #N/A | AD17: =IF(Switches!AA2=1,Switches!BC26,Switches!BC28) -> 0 | AE17: 90 | AF17: N/A | AG17: =SPAT3!L4 -> 0 | AH17: =SPAT3!L5 -> 0
B18: =IF(Switches!BC3>2,Qualer!AB18,"") | C18: =IF(Switches!BC3>2,Qualer!AC18,"") | D18: =IF(Switches!BC3>2,Qualer!AD18,"") | E18: =IF(Switches!BC3>2,Qualer!AE18,"") | F18: =IF(Switches!BC3>2,Qualer!AF18,"") | G18: =IF(Switches!BC3>2,Qualer!AG18,"") | H18: =IF(Switches!BC3>2,Qualer!AH18,"") | AB18: =IF(Switches!AA2=1,"SPAT-3-Z","") -> SPAT-3-Z | AC18: =AC16 -> #N/A | AD18: =IF(Switches!AA2=1,Switches!BC27,"") -> 0 | AE18: =AE16 -> 90 | AF18: =AF16 -> N/A | AG18: =AG16 -> 0 | AH18: =AH16 -> 0
B19: =IF(Switches!BE3>1,Qualer!AB19,"") | C19: =IF(Switches!BE3>1,Qualer!AC19,"") | D19: =IF(Switches!BE3>1,Qualer!AD19,"") | E19: =IF(Switches!BE3>1,Qualer!AE19,"") | F19: =IF(Switches!BE3>1,Qualer!AF19,"") | G19: =IF(Switches!BE3>1,Qualer!AG19,"") | H19: =IF(Switches!BE3>1,Qualer!AH19,"") | AB19: Psize | AC19: =Switches!K4 -> #N/A | AD19: =Probing!C20 -> #N/A | AE19: 55 | AF19: =Probing!AR14 -> #N/A | AG19: =Probing!C3 -> 0 | AH19: =Probing!D3 -> 0
B20: =IF(Switches!BE3>1,Qualer!AB20,"") | C20: =IF(Switches!BE3>1,Qualer!AC20,"") | D20: =IF(Switches!BE3>1,Qualer!AD20,"") | E20: =IF(Switches!BE3>1,Qualer!AE20,"") | F20: =F19 | G20: =G19 | H20: =H19 | AB20: Pform | AC20: =Switches!L4 -> #N/A | AD20: =Probing!C21 -> 0 | AE20: 55 | AF20: =AF19 -> #N/A | AG20: =AG19 -> 0 | AH20: =AH19 -> 0
B21: =IF(Switches!BF3>1,Qualer!AB21,"") | C21: =IF(Switches!BF3>1,Qualer!AC21,"") | D21: =IF(Switches!BF3>1,Qualer!AD21,"") | E21: =IF(Switches!BF3>1,Qualer!AE21,"") | F21: =IF(Switches!BF3>1,Qualer!AF21,"") | G21: =IF(Switches!BF3>1,Qualer!AG21,"") | H21: =IF(Switches!BF3>1,Qualer!AH21,"") | AB21: Ldia | AC21: =Switches!M4 -> #N/A | AD21: ='Articulated Location'!D14 -> 0 | AE21: 55 | AF21: ='Articulated Location'!AR14 -> #N/A | AG21: ='Articulated Location'!C1 -> 0 | AH21: ='Articulated Location'!E1 -> 0
B22: =IF(Switches!BG3>1,Qualer!AB22,"") | C22: =IF(Switches!BG3>1,Qualer!AC22,"") | D22: =IF(Switches!BG3>1,Qualer!AD22,"") | E22: =IF(Switches!BG3>1,Qualer!AE22,"") | F22: =IF(Switches!BG3>1,Qualer!AF22,"") | G22: =IF(Switches!BG3>1,Qualer!AG22,"") | H22: =IF(Switches!BG3>1,Qualer!AH22,"") | AB22: EDPT | AC22: =IF(Switches!N4="N/A",Switches!N5,Switches!N4) -> Capability | AD22: =EDPT!F10 -> #N/A | AE22: 55 | AF22: =EDPT!AR14 -> #N/A | AG22: =EDPT!C3 -> 0 | AH22: =EDPT!C4 -> 0
A24: Report | B24: =Info!B25 -> 0 | E24: LLP | H24: Attributes
A25: Item | B25: =Info!D29 | H25: Condition: | I25: Used
H26: Tolerance Source: | I26: =IF(Switches!U8=1,Switches!U3,Switches!U4) -> Manufacturer
A27: Pages | B27: 2 | H27: Work Procedure: | I27: WP251895
B29: Test | C29: Tolerance | D29: Result | E29: Uncertainty | F29: Standard | G29: Temp | H29: RH | AB29: Test | AC29: Tolerance | AD29: Result | AE29: Uncertainty | AF29: Standard | AG29: Temp | AH29: RH
B30: =IF(Info!$B$28="","",AB30) | C30: =IF(Info!$B$28="","",AC30) | D30: =IF(Info!$B$28="","",AD30) | E30: =IF(Info!$B$28="","",AE30) | F30: =IF(Info!$B$28="","",AF30) | G30: =IF(Info!$B$28="","",AG30) | H30: =IF(Info!$B$28="","",AH30) | AB30: Accuracy | AC30: =Switches!BX3 -> N/A | AD30: =Info!D31 -> 0 | AE30: 55 | AF30: =LLP!AR14 -> #N/A | AG30: =LLP!C1 -> 0 | AH30: =LLP!E1 -> 0
A32: Report | B32: =Info!B33 -> 0 | E32: 8-Axis | H32: Attributes
A33: Item | B33: =Info!D37 | H33: Condition: | I33: Used
H34: Tolerance Source: | I34: =IF(Switches!U10=1,Switches!U3,Switches!U4) -> Manufacturer
A35: Pages | B35: 2 | H35: Work Procedure: | I35: WP251895
B37: Test | C37: Tolerance | D37: Result | E37: Uncertainty | F37: Standard | G37: Temp | H37: RH | AB37: Test | AC37: Tolerance | AD37: Result | AE37: Uncertainty | AF37: Standard | AG37: Temp | AH37: RH
B38: =IF(Info!$B$36="","",AB38) | C38: =IF(Info!$B$36="","",AC38) | D38: =IF(Info!$B$36="","",AD38) | E38: =IF(Info!$B$36="","",AE38) | F38: =IF(Info!$B$36="","",AF38) | G38: =IF(Info!$B$36="","",AG38) | H38: =IF(Info!$B$36="","",AH38) | AB38: Accuracy | AC38: =Switches!CM3 -> N/A | AD38: =Info!D39 -> 0 | AE38: 55 | AF38: ='8-Axis'!AR14 -> #N/A | AG38: ='8-Axis'!C1 -> 0 | AH38: ='8-Axis'!E1 -> 0

Sheet SPAT1
A1: ="Report No. "&AS4 -> Report No. 0 | K1: =AV10 -> Page 0 of 1
M2: =IF(AU9=TRUE,"SPAT (0-20%)","SPAT") -> SPAT
F3: Johnson Gage and Inspection, Inc. | AS3: Imported from other sheets
F4: 5920 West 21st Street North, Wichita, KS 67205 | M4: Temperature | O4: Metric | AR4: Report No.: | AS4: =Info!B1 -> 0
F5: Phone 316.943.7532 FAX 316.944.6256 | M5: Humidity | AR5: Customer: | AS5: =Info!B2 -> 0
AR6: Machine I.D: | AS6: =Info!D14 -> #N/A
F7: =IF(AU9=TRUE,"Single Point Articulation Test Record (0-20%)","Single Point Articulation Test Record") -> Single Point Articulation Test Record | N7: Raw Data | AR7: Serial No: | AS7: =Info!B8 -> 0
M8: X | N8: Y | O8: Z | AR8: Date Tested: | AS8: =Info!B5 -> 0
B9: Customer: | C9: =AS5 -> 0 | L9: 1 | AR9: Tested By: | AS9: =Info!B6 -> 0 | AT9: 3 Loc: | AU9: =IF(Switches!BC3=3,TRUE,FALSE) -> FALSE
B10: Machine I.D: | C10: =AS6 -> #N/A | I10: Date Tested: | J10: =AS8 -> 0 | L10: 2 | AR10: Page: | AS10: =Switches!BJ3 -> 0 | AT10: Pages: | AU10: =Switches!BI8 -> 1 | AV10: ="Page "&AS10&" of "&AU10 -> Page 0 of 1
B11: Serial No: | C11: =AS7 -> 0 | I11: Tested By: | J11: =AS9 -> 0 | L11: 3 | AR11: Tolerance: | AS11: =Switches!I4 -> #N/A | AT11: Metric: | AU11: =Switches!Y2 -> FALSE
L12: 4 | AR12: Tolerance Method: | AS12: =Switches!AA2 -> 1 | AT12: =IF(AS12=1,Switches!AB2,IF(AS12=2,Switches!AB3,"error")) -> (Max-Min/2) | AV12: ="Tolerance for this unit @ "&AS12&": " -> Tolerance for this unit @ 1:
L13: 5 | AS13: Live Updating | AW13: Centered Data | AZ13: Sum of squares | BA13: Vectored Deviation | BD13: Absolute Centered Data | BH13: +TOL | BI13: -TOL | BK13: Metric
D14: Test | F14: X | G14: Y | H14: Z | L14: 6 | AR14: X | AS14: Y | AT14: Z | AV14: X | AW14: Y | AX14: Z | BC14: X | BD14: Y | BE14: Z
D15: 1 | F15: =AV15 -> 0 | G15: =AW15 -> 0 | H15: =AX15 -> 0 | L15: 7 | AR15: =IF(M9="",0,IF(BK15=TRUE,M9/25.4,M9)) -> 0 | AS15: =IF(N9="",0,IF(BK15=TRUE,N9/25.4,N9)) -> 0 | AT15: =IF(O9="",0,IF(BK15=TRUE,O9/25.4,O9)) -> 0 | AV15: =AR15-AR29 -> 0 | AW15: =AS15-AS29 -> 0 | AX15: =AT15-AT29 -> 0 | AZ15: =SUMSQ(AV15:AX15) -> 0 | BA15: =SQRT(AZ15) -> 0 | BC15: =ABS(AV15) -> 0 | BD15: =ABS(AW15) -> 0 | BE15: =ABS(AX15) -> 0 | BH15: =AS11 -> #N/A | BI15: =BH15*(-1) -> #N/A | BK15: =AU11 -> FALSE
D16: 2 | F16: =AV16 -> 0 | G16: =AW16 -> 0 | H16: =AX16 -> 0 | L16: 8 | AR16: =IF(M10="",AR15,IF(BK16=TRUE,M10/25.4,M10)) -> 0 | AS16: =IF(N10="",AS15,IF(BK16=TRUE,N10/25.4,N10)) -> 0 | AT16: =IF(O10="",AT15,IF(BK16=TRUE,O10/25.4,O10)) -> 0 | AV16: =AR16-AR29 -> 0 | AW16: =AS16-AS29 -> 0 | AX16: =AT16-AT29 -> 0 | AZ16: =SUMSQ(AV16:AX16) -> 0 | BA16: =SQRT(AZ16) -> 0 | BC16: =ABS(AV16) -> 0 | BD16: =ABS(AW16) -> 0 | BE16: =ABS(AX16) -> 0 | BH16: =BH15 -> #N/A | BI16: =BI15 -> #N/A | BK16: =BK15 -> FALSE
D17: 3 | F17: =AV17 -> 0 | G17: =AW17 -> 0 | H17: =AX17 -> 0 | L17: 9 | AR17: =IF(M11="",AVERAGE(AR15:AR16),IF(BK17=TRUE,M11/25.4,M11)) -> 0 | AS17: =IF(N11="",AVERAGE(AS15:AS16),IF(BK17=TRUE,N11/25.4,N11)) -> 0 | AT17: =IF(O11="",AVERAGE(AT15:AT16),IF(BK17=TRUE,O11/25.4,O11)) -> 0 | AV17: =AR17-AR29 -> 0 | AW17: =AS17-AS29 -> 0 | AX17: =AT17-AT29 -> 0 | AZ17: =SUMSQ(AV17:AX17) -> 0 | BA17: =SQRT(AZ17) -> 0 | BC17: =ABS(AV17) -> 0 | BD17: =ABS(AW17) -> 0 | BE17: =ABS(AX17) -> 0 | BH17: =BH16 -> #N/A | BI17: =BI16 -> #N/A | BK17: =BK16 -> FALSE
D18: 4 | F18: =AV18 -> 0 | G18: =AW18 -> 0 | H18: =AX18 -> 0 | L18: 10 | AR18: =IF(M12="",AVERAGE(AR15:AR17),IF(BK18=TRUE,M12/25.4,M12)) -> 0 | AS18: =IF(N12="",AVERAGE(AS15:AS17),IF(BK18=TRUE,N12/25.4,N12)) -> 0 | AT18: =IF(O12="",AVERAGE(AT15:AT17),IF(BK18=TRUE,O12/25.4,O12)) -> 0 | AV18: =AR18-AR29 -> 0 | AW18: =AS18-AS29 -> 0 | AX18: =AT18-AT29 -> 0 | AZ18: =SUMSQ(AV18:AX18) -> 0 | BA18: =SQRT(AZ18) -> 0 | BC18: =ABS(AV18) -> 0 | BD18: =ABS(AW18) -> 0 | BE18: =ABS(AX18) -> 0 | BH18: =BH17 -> #N/A | BI18: =BI17 -> #N/A | BK18: =BK17 -> FALSE
D19: 5 | F19: =AV19 -> 0 | G19: =AW19 -> 0 | H19: =AX19 -> 0 | L19: (Max-Min/2): | M19: =AR30 -> 0 | N19: =AS30 -> 0 | O19: =AT30 -> 0 | AR19: =IF(M13="",AVERAGE(AR15:AR18),IF(BK19=TRUE,M13/25.4,M13)) -> 0 | AS19: =IF(N13="",AVERAGE(AS15:AS18),IF(BK19=TRUE,N13/25.4,N13)) -> 0 | AT19: =IF(O13="",AVERAGE(AT15:AT18),IF(BK19=TRUE,O13/25.4,O13)) -> 0 | AV19: =AR19-AR29 -> 0 | AW19: =AS19-AS29 -> 0 | AX19: =AT19-AT29 -> 0 | AZ19: =SUMSQ(AV19:AX19) -> 0 | BA19: =SQRT(AZ19) -> 0 | BC19: =ABS(AV19) -> 0 | BD19: =ABS(AW19) -> 0 | BE19: =ABS(AX19) -> 0 | BH19: =BH18 -> #N/A | BI19: =BI18 -> #N/A | BK19: =BK18 -> FALSE
D20: 6 | F20: =AV20 -> 0 | G20: =AW20 -> 0 | H20: =AX20 -> 0 | L20: 2 Sigma: | N20: =BA37 -> 0 | AR20: =IF(M14="",AVERAGE(AR15:AR19),IF(BK20=TRUE,M14/25.4,M14)) -> 0 | AS20: =IF(N14="",AVERAGE(AS15:AS19),IF(BK20=TRUE,N14/25.4,N14)) -> 0 | AT20: =IF(O14="",AVERAGE(AT15:AT19),IF(BK20=TRUE,O14/25.4,O14)) -> 0 | AV20: =AR20-AR29 -> 0 | AW20: =AS20-AS29 -> 0 | AX20: =AT20-AT29 -> 0 | AZ20: =SUMSQ(AV20:AX20) -> 0 | BA20: =SQRT(AZ20) -> 0 | BC20: =ABS(AV20) -> 0 | BD20: =ABS(AW20) -> 0 | BE20: =ABS(AX20) -> 0 | BH20: =BH19 -> #N/A | BI20: =BI19 -> #N/A | BK20: =BK19 -> FALSE
D21: 7 | F21: =AV21 -> 0 | G21: =AW21 -> 0 | H21: =AX21 -> 0 | L21: Tolerance: | M21: =AT12 -> (Max-Min/2) | N21: =AS11 -> #N/A | AR21: =IF(M15="",AVERAGE(AR15:AR20),IF(BK21=TRUE,M15/25.4,M15)) -> 0 | AS21: =IF(N15="",AVERAGE(AS15:AS20),IF(BK21=TRUE,N15/25.4,N15)) -> 0 | AT21: =IF(O15="",AVERAGE(AT15:AT20),IF(BK21=TRUE,O15/25.4,O15)) -> 0 | AV21: =AR21-AR29 -> 0 | AW21: =AS21-AS29 -> 0 | AX21: =AT21-AT29 -> 0 | AZ21: =SUMSQ(AV21:AX21) -> 0 | BA21: =SQRT(AZ21) -> 0 | BC21: =ABS(AV21) -> 0 | BD21: =ABS(AW21) -> 0 | BE21: =ABS(AX21) -> 0 | BH21: =BH20 -> #N/A | BI21: =BI20 -> #N/A | BK21: =BK20 -> FALSE
D22: 8 | F22: =AV22 -> 0 | G22: =AW22 -> 0 | H22: =AX22 -> 0 | M22: Result: | N22: =IF(AS12=1,MAX(M19:O19),N20) -> 0 | AR22: =IF(M16="",AVERAGE(AR15:AR21),IF(BK22=TRUE,M16/25.4,M16)) -> 0 | AS22: =IF(N16="",AVERAGE(AS15:AS21),IF(BK22=TRUE,N16/25.4,N16)) -> 0 | AT22: =IF(O16="",AVERAGE(AT15:AT21),IF(BK22=TRUE,O16/25.4,O16)) -> 0 | AV22: =AR22-AR29 -> 0 | AW22: =AS22-AS29 -> 0 | AX22: =AT22-AT29 -> 0 | AZ22: =SUMSQ(AV22:AX22) -> 0 | BA22: =SQRT(AZ22) -> 0 | BC22: =ABS(AV22) -> 0 | BD22: =ABS(AW22) -> 0 | BE22: =ABS(AX22) -> 0 | BH22: =BH21 -> #N/A | BI22: =BI21 -> #N/A | BK22: =BK21 -> FALSE
D23: 9 | F23: =AV23 -> 0 | G23: =AW23 -> 0 | H23: =AX23 -> 0 | L23: Scroll left or right | AR23: =IF(M17="",AVERAGE(AR15:AR22),IF(BK23=TRUE,M17/25.4,M17)) -> 0 | AS23: =IF(N17="",AVERAGE(AS15:AS22),IF(BK23=TRUE,N17/25.4,N17)) -> 0 | AT23: =IF(O17="",AVERAGE(AT15:AT22),IF(BK23=TRUE,O17/25.4,O17)) -> 0 | AV23: =AR23-AR29 -> 0 | AW23: =AS23-AS29 -> 0 | AX23: =AT23-AT29 -> 0 | AZ23: =SUMSQ(AV23:AX23) -> 0 | BA23: =SQRT(AZ23) -> 0 | BC23: =ABS(AV23) -> 0 | BD23: =ABS(AW23) -> 0 | BE23: =ABS(AX23) -> 0 | BH23: =BH22 -> #N/A | BI23: =BI22 -> #N/A | BK23: =BK22 -> FALSE
D24: 10 | F24: =AV24 -> 0 | G24: =AW24 -> 0 | H24: =AX24 -> 0 | L24: <-- Printable Data Sheet | AR24: =IF(M18="",AVERAGE(AR15:AR23),IF(BK24=TRUE,M18/25.4,M18)) -> 0 | AS24: =IF(N18="",AVERAGE(AS15:AS23),IF(BK24=TRUE,N18/25.4,N18)) -> 0 | AT24: =IF(O18="",AVERAGE(AT15:AT23),IF(BK24=TRUE,O18/25.4,O18)) -> 0 | AV24: =AR24-AR29 -> 0 | AW24: =AS24-AS29 -> 0 | AX24: =AT24-AT29 -> 0 | AZ24: =SUMSQ(AV24:AX24) -> 0 | BA24: =SQRT(AZ24) -> 0 | BC24: =ABS(AV24) -> 0 | BD24: =ABS(AW24) -> 0 | BE24: =ABS(AX24) -> 0 | BH24: =BH23 -> #N/A | BI24: =BI23 -> #N/A | BK24: =BK23 -> FALSE
L25: Calculations -->
D26: Minimum: | F26: =AV26 -> 0 | G26: =AW26 -> 0 | H26: =AX26 -> 0 | AQ26: Minimum: | AR26: =MIN(AR15:AR24) -> 0 | AS26: =MIN(AS15:AS24) -> 0 | AT26: =MIN(AT15:AT24) -> 0 | AU26: Minimum: | AV26: =MIN(AV15:AV24) -> 0 | AW26: =MIN(AW15:AW24) -> 0 | AX26: =MIN(AX15:AX24) -> 0 | AZ26: Minimum: | BA26: =MIN(BA15:BA24) -> 0
D27: Maximum: | F27: =AV27 -> 0 | G27: =AW27 -> 0 | H27: =AX27 -> 0 | AQ27: Maximum: | AR27: =MAX(AR15:AR24) -> 0 | AS27: =MAX(AS15:AS24) -> 0 | AT27: =MAX(AT15:AT24) -> 0 | AU27: Maximum: | AV27: =MAX(AV15:AV24) -> 0 | AW27: =MAX(AW15:AW24) -> 0 | AX27: =MAX(AX15:AX24) -> 0 | AZ27: Maximum: | BA27: =MAX(BA15:BA24) -> 0
D28: Average Deviation: | F28: =AV31 -> 0 | G28: =AW31 -> 0 | H28: =AX31 -> 0 | AQ28: Range: | AR28: =AR27-AR26 -> 0 | AS28: =AS27-AS26 -> 0 | AT28: =AT27-AT26 -> 0 | AU28: Range: | AV28: =AV27-AV26 -> 0 | AW28: =AW27-AW26 -> 0 | AX28: =AX27-AX26 -> 0 | AZ28: Range: | BA28: =BA27-BA26 -> 0
D29: Standard Deviation: | F29: =AV29 -> 0 | G29: =AW29 -> 0 | H29: =AX29 -> 0 | AQ29: Corrector: | AR29: =AVERAGE(AR15:AR24) -> 0 | AS29: =AVERAGE(AS15:AS24) -> 0 | AT29: =AVERAGE(AT15:AT24) -> 0 | AU29: 1 Std. Dev: | AV29: =_xlfn.STDEV.S(AV15:AV24) -> 0 | AW29: =_xlfn.STDEV.S(AW15:AW24) -> 0 | AX29: =_xlfn.STDEV.S(AX15:AX24) -> 0 | AZ29: 1 Std. Dev: | BA29: =_xlfn.STDEV.S(BA15:BA24) -> 0
D30: 2 Standard Deviations: | F30: =AV30 -> 0 | G30: =AW30 -> 0 | H30: =AX30 -> 0 | AQ30: (Max-Min/2) | AR30: =AR28/2 -> 0 | AS30: =AS28/2 -> 0 | AT30: =AT28/2 -> 0 | AU30: 2 Std. Dev: | AV30: =2*AV29 -> 0 | AW30: =2*AW29 -> 0 | AX30: =2*AX29 -> 0 | AZ30: 2 Std. Dev: | BA30: =2*BA29 -> 0
D31: (Max-Min)/2: | F31: =AR30 -> 0 | G31: =AS30 -> 0 | H31: =AT30 -> 0 | AU31: Average Deviation: | AV31: =AVERAGE(BC15:BC24) -> 0 | AW31: =AVERAGE(BD15:BD24) -> 0 | AX31: =AVERAGE(BE15:BE24) -> 0 | AZ31: Average: | BA31: =AVERAGE(BA15:BA24) -> 0
AU32: Average Deviation + 2 Sigma: | AV32: =AV31+AV30 -> 0 | AW32: =AW31+AW30 -> 0 | AX32: =AX31+AX30 -> 0 | AZ32: Average + 2 Sigma: | BA32: =BA31+BA30 -> 0
H33: Deviation @ 2 sigma expressed as a vector: | I33: =BA37 -> 0
H34: Maximum Deviation expressed as a vector: | I34: =BA27 -> 0 | BA34: =SUMSQ(BA15:BA24) -> 0
BA35: =BA34/9 -> 0
H36: ="Tolerance for this unit @ "&AT12&":" -> Tolerance for this unit @ (Max-Min/2): | I36: =AS11 -> #N/A | AZ36: Vectored Deviation at 1 Standard Deviation | BA36: =SQRT(BA35) -> 0
AZ37: Vectored Deviation at 2 Standard Deviations | BA37: =2*BA36 -> 0
D38: All results shown are in inches unless otherwise specified.

Sheet SPAT2
A1: ="Report No. "&AS4 -> Report No. 0 | K1: =AV10 -> Page 1 of 1
M2: SPAT (20-80%)
F3: Johnson Gage and Inspection, Inc. | AS3: Imported from other sheets
F4: 5920 West 21st Street North, Wichita, KS 67205 | M4: Temperature | O4: Metric | AR4: Report No.: | AS4: =Info!B1 -> 0
F5: Phone 316.943.7532 FAX 316.944.6256 | M5: Humidity | AR5: Customer: | AS5: =Info!B2 -> 0
AR6: Machine I.D: | AS6: =Info!D14 -> #N/A
F7: Single Point Articulation Test Record (20-80%) | N7: Raw Data | AR7: Serial No: | AS7: =Info!B8 -> 0
M8: X | N8: Y | O8: Z | AR8: Date Tested: | AS8: =Info!B5 -> 0
B9: Customer: | C9: =AS5 -> 0 | L9: 1 | AR9: Tested By: | AS9: =Info!B6 -> 0 | AT9: 3 Loc: | AU9: =IF(Switches!BC3=3,TRUE,FALSE) -> FALSE
B10: Machine I.D: | C10: =AS6 -> #N/A | I10: Date Tested: | J10: =AS8 -> 0 | L10: 2 | AR10: Page: | AS10: =Switches!BJ3+1 -> 1 | AT10: Pages: | AU10: =Switches!BI8 -> 1 | AV10: ="Page "&AS10&" of "&AU10 -> Page 1 of 1
B11: Serial No: | C11: =AS7 -> 0 | I11: Tested By: | J11: =AS9 -> 0 | L11: 3 | AR11: Tolerance: | AS11: =Switches!I4 -> #N/A | AT11: Metric: | AU11: =Switches!Y3 -> FALSE
L12: 4 | AR12: Tolerance Method: | AS12: =Switches!AA2 -> 1 | AT12: =IF(AS12=1,Switches!AB2,IF(AS12=2,Switches!AB3,"error")) -> (Max-Min/2) | AV12: ="Tolerance for this unit @ "&AS12&": " -> Tolerance for this unit @ 1:
L13: 5 | AS13: Live Updating | AW13: Centered Data | AZ13: Sum of squares | BA13: Vectored Deviation | BD13: Absolute Centered Data | BH13: +TOL | BI13: -TOL | BK13: Metric
D14: Test | F14: X | G14: Y | H14: Z | L14: 6 | AR14: X | AS14: Y | AT14: Z | AV14: X | AW14: Y | AX14: Z | BC14: X | BD14: Y | BE14: Z
D15: 1 | F15: =AV15 -> 0 | G15: =AW15 -> 0 | H15: =AX15 -> 0 | L15: 7 | AR15: =IF(M9="",0,IF(BK15=TRUE,M9/25.4,M9)) -> 0 | AS15: =IF(N9="",0,IF(BK15=TRUE,N9/25.4,N9)) -> 0 | AT15: =IF(O9="",0,IF(BK15=TRUE,O9/25.4,O9)) -> 0 | AV15: =AR15-AR29 -> 0 | AW15: =AS15-AS29 -> 0 | AX15: =AT15-AT29 -> 0 | AZ15: =SUMSQ(AV15:AX15) -> 0 | BA15: =SQRT(AZ15) -> 0 | BC15: =ABS(AV15) -> 0 | BD15: =ABS(AW15) -> 0 | BE15: =ABS(AX15) -> 0 | BH15: =AS11 -> #N/A | BI15: =BH15*(-1) -> #N/A | BK15: =AU11 -> FALSE
D16: 2 | F16: =AV16 -> 0 | G16: =AW16 -> 0 | H16: =AX16 -> 0 | L16: 8 | AR16: =IF(M10="",AR15,IF(BK16=TRUE,M10/25.4,M10)) -> 0 | AS16: =IF(N10="",AS15,IF(BK16=TRUE,N10/25.4,N10)) -> 0 | AT16: =IF(O10="",AT15,IF(BK16=TRUE,O10/25.4,O10)) -> 0 | AV16: =AR16-AR29 -> 0 | AW16: =AS16-AS29 -> 0 | AX16: =AT16-AT29 -> 0 | AZ16: =SUMSQ(AV16:AX16) -> 0 | BA16: =SQRT(AZ16) -> 0 | BC16: =ABS(AV16) -> 0 | BD16: =ABS(AW16) -> 0 | BE16: =ABS(AX16) -> 0 | BH16: =BH15 -> #N/A | BI16: =BI15 -> #N/A | BK16: =BK15 -> FALSE
D17: 3 | F17: =AV17 -> 0 | G17: =AW17 -> 0 | H17: =AX17 -> 0 | L17: 9 | AR17: =IF(M11="",AVERAGE(AR15:AR16),IF(BK17=TRUE,M11/25.4,M11)) -> 0 | AS17: =IF(N11="",AVERAGE(AS15:AS16),IF(BK17=TRUE,N11/25.4,N11)) -> 0 | AT17: =IF(O11="",AVERAGE(AT15:AT16),IF(BK17=TRUE,O11/25.4,O11)) -> 0 | AV17: =AR17-AR29 -> 0 | AW17: =AS17-AS29 -> 0 | AX17: =AT17-AT29 -> 0 | AZ17: =SUMSQ(AV17:AX17) -> 0 | BA17: =SQRT(AZ17) -> 0 | BC17: =ABS(AV17) -> 0 | BD17: =ABS(AW17) -> 0 | BE17: =ABS(AX17) -> 0 | BH17: =BH16 -> #N/A | BI17: =BI16 -> #N/A | BK17: =BK16 -> FALSE
D18: 4 | F18: =AV18 -> 0 | G18: =AW18 -> 0 | H18: =AX18 -> 0 | L18: 10 | AR18: =IF(M12="",AVERAGE(AR15:AR17),IF(BK18=TRUE,M12/25.4,M12)) -> 0 | AS18: =IF(N12="",AVERAGE(AS15:AS17),IF(BK18=TRUE,N12/25.4,N12)) -> 0 | AT18: =IF(O12="",AVERAGE(AT15:AT17),IF(BK18=TRUE,O12/25.4,O12)) -> 0 | AV18: =AR18-AR29 -> 0 | AW18: =AS18-AS29 -> 0 | AX18: =AT18-AT29 -> 0 | AZ18: =SUMSQ(AV18:AX18) -> 0 | BA18: =SQRT(AZ18) -> 0 | BC18: =ABS(AV18) -> 0 | BD18: =ABS(AW18) -> 0 | BE18: =ABS(AX18) -> 0 | BH18: =BH17 -> #N/A | BI18: =BI17 -> #N/A | BK18: =BK17 -> FALSE
D19: 5 | F19: =AV19 -> 0 | G19: =AW19 -> 0 | H19: =AX19 -> 0 | L19: (Max-Min/2): | M19: =AR30 -> 0 | N19: =AS30 -> 0 | O19: =AT30 -> 0 | AR19: =IF(M13="",AVERAGE(AR15:AR18),IF(BK19=TRUE,M13/25.4,M13)) -> 0 | AS19: =IF(N13="",AVERAGE(AS15:AS18),IF(BK19=TRUE,N13/25.4,N13)) -> 0 | AT19: =IF(O13="",AVERAGE(AT15:AT18),IF(BK19=TRUE,O13/25.4,O13)) -> 0 | AV19: =AR19-AR29 -> 0 | AW19: =AS19-AS29 -> 0 | AX19: =AT19-AT29 -> 0 | AZ19: =SUMSQ(AV19:AX19) -> 0 | BA19: =SQRT(AZ19) -> 0 | BC19: =ABS(AV19) -> 0 | BD19: =ABS(AW19) -> 0 | BE19: =ABS(AX19) -> 0 | BH19: =BH18 -> #N/A | BI19: =BI18 -> #N/A | BK19: =BK18 -> FALSE
D20: 6 | F20: =AV20 -> 0 | G20: =AW20 -> 0 | H20: =AX20 -> 0 | L20: 2 Sigma: | N20: =BA37 -> 0 | AR20: =IF(M14="",AVERAGE(AR15:AR19),IF(BK20=TRUE,M14/25.4,M14)) -> 0 | AS20: =IF(N14="",AVERAGE(AS15:AS19),IF(BK20=TRUE,N14/25.4,N14)) -> 0 | AT20: =IF(O14="",AVERAGE(AT15:AT19),IF(BK20=TRUE,O14/25.4,O14)) -> 0 | AV20: =AR20-AR29 -> 0 | AW20: =AS20-AS29 -> 0 | AX20: =AT20-AT29 -> 0 | AZ20: =SUMSQ(AV20:AX20) -> 0 | BA20: =SQRT(AZ20) -> 0 | BC20: =ABS(AV20) -> 0 | BD20: =ABS(AW20) -> 0 | BE20: =ABS(AX20) -> 0 | BH20: =BH19 -> #N/A | BI20: =BI19 -> #N/A | BK20: =BK19 -> FALSE
D21: 7 | F21: =AV21 -> 0 | G21: =AW21 -> 0 | H21: =AX21 -> 0 | L21: Tolerance: | M21: =AT12 -> (Max-Min/2) | N21: =AS11 -> #N/A | AR21: =IF(M15="",AVERAGE(AR15:AR20),IF(BK21=TRUE,M15/25.4,M15)) -> 0 | AS21: =IF(N15="",AVERAGE(AS15:AS20),IF(BK21=TRUE,N15/25.4,N15)) -> 0 | AT21: =IF(O15="",AVERAGE(AT15:AT20),IF(BK21=TRUE,O15/25.4,O15)) -> 0 | AV21: =AR21-AR29 -> 0 | AW21: =AS21-AS29 -> 0 | AX21: =AT21-AT29 -> 0 | AZ21: =SUMSQ(AV21:AX21) -> 0 | BA21: =SQRT(AZ21) -> 0 | BC21: =ABS(AV21) -> 0 | BD21: =ABS(AW21) -> 0 | BE21: =ABS(AX21) -> 0 | BH21: =BH20 -> #N/A | BI21: =BI20 -> #N/A | BK21: =BK20 -> FALSE
D22: 8 | F22: =AV22 -> 0 | G22: =AW22 -> 0 | H22: =AX22 -> 0 | M22: Result: | N22: =IF(AS12=1,MAX(M19:O19),N20) -> 0 | AR22: =IF(M16="",AVERAGE(AR15:AR21),IF(BK22=TRUE,M16/25.4,M16)) -> 0 | AS22: =IF(N16="",AVERAGE(AS15:AS21),IF(BK22=TRUE,N16/25.4,N16)) -> 0 | AT22: =IF(O16="",AVERAGE(AT15:AT21),IF(BK22=TRUE,O16/25.4,O16)) -> 0 | AV22: =AR22-AR29 -> 0 | AW22: =AS22-AS29 -> 0 | AX22: =AT22-AT29 -> 0 | AZ22: =SUMSQ(AV22:AX22) -> 0 | BA22: =SQRT(AZ22) -> 0 | BC22: =ABS(AV22) -> 0 | BD22: =ABS(AW22) -> 0 | BE22: =ABS(AX22) -> 0 | BH22: =BH21 -> #N/A | BI22: =BI21 -> #N/A | BK22: =BK21 -> FALSE
D23: 9 | F23: =AV23 -> 0 | G23: =AW23 -> 0 | H23: =AX23 -> 0 | L23: Scroll left or right | AR23: =IF(M17="",AVERAGE(AR15:AR22),IF(BK23=TRUE,M17/25.4,M17)) -> 0 | AS23: =IF(N17="",AVERAGE(AS15:AS22),IF(BK23=TRUE,N17/25.4,N17)) -> 0 | AT23: =IF(O17="",AVERAGE(AT15:AT22),IF(BK23=TRUE,O17/25.4,O17)) -> 0 | AV23: =AR23-AR29 -> 0 | AW23: =AS23-AS29 -> 0 | AX23: =AT23-AT29 -> 0 | AZ23: =SUMSQ(AV23:AX23) -> 0 | BA23: =SQRT(AZ23) -> 0 | BC23: =ABS(AV23) -> 0 | BD23: =ABS(AW23) -> 0 | BE23: =ABS(AX23) -> 0 | BH23: =BH22 -> #N/A | BI23: =BI22 -> #N/A | BK23: =BK22 -> FALSE
D24: 10 | F24: =AV24 -> 0 | G24: =AW24 -> 0 | H24: =AX24 -> 0 | L24: <-- Printable Data Sheet | AR24: =IF(M18="",AVERAGE(AR15:AR23),IF(BK24=TRUE,M18/25.4,M18)) -> 0 | AS24: =IF(N18="",AVERAGE(AS15:AS23),IF(BK24=TRUE,N18/25.4,N18)) -> 0 | AT24: =IF(O18="",AVERAGE(AT15:AT23),IF(BK24=TRUE,O18/25.4,O18)) -> 0 | AV24: =AR24-AR29 -> 0 | AW24: =AS24-AS29 -> 0 | AX24: =AT24-AT29 -> 0 | AZ24: =SUMSQ(AV24:AX24) -> 0 | BA24: =SQRT(AZ24) -> 0 | BC24: =ABS(AV24) -> 0 | BD24: =ABS(AW24) -> 0 | BE24: =ABS(AX24) -> 0 | BH24: =BH23 -> #N/A | BI24: =BI23 -> #N/A | BK24: =BK23 -> FALSE
L25: Calculations -->
D26: Minimum: | F26: =AV26 -> 0 | G26: =AW26 -> 0 | H26: =AX26 -> 0 | AQ26: Minimum: | AR26: =MIN(AR15:AR24) -> 0 | AS26: =MIN(AS15:AS24) -> 0 | AT26: =MIN(AT15:AT24) -> 0 | AU26: Minimum: | AV26: =MIN(AV15:AV24) -> 0 | AW26: =MIN(AW15:AW24) -> 0 | AX26: =MIN(AX15:AX24) -> 0 | AZ26: Minimum: | BA26: =MIN(BA15:BA24) -> 0
D27: Maximum: | F27: =AV27 -> 0 | G27: =AW27 -> 0 | H27: =AX27 -> 0 | AQ27: Maximum: | AR27: =MAX(AR15:AR24) -> 0 | AS27: =MAX(AS15:AS24) -> 0 | AT27: =MAX(AT15:AT24) -> 0 | AU27: Maximum: | AV27: =MAX(AV15:AV24) -> 0 | AW27: =MAX(AW15:AW24) -> 0 | AX27: =MAX(AX15:AX24) -> 0 | AZ27: Maximum: | BA27: =MAX(BA15:BA24) -> 0
D28: Average Deviation: | F28: =AV31 -> 0 | G28: =AW31 -> 0 | H28: =AX31 -> 0 | AQ28: Range: | AR28: =AR27-AR26 -> 0 | AS28: =AS27-AS26 -> 0 | AT28: =AT27-AT26 -> 0 | AU28: Range: | AV28: =AV27-AV26 -> 0 | AW28: =AW27-AW26 -> 0 | AX28: =AX27-AX26 -> 0 | AZ28: Range: | BA28: =BA27-BA26 -> 0
D29: Standard Deviation: | F29: =AV29 -> 0 | G29: =AW29 -> 0 | H29: =AX29 -> 0 | AQ29: Corrector: | AR29: =AVERAGE(AR15:AR24) -> 0 | AS29: =AVERAGE(AS15:AS24) -> 0 | AT29: =AVERAGE(AT15:AT24) -> 0 | AU29: 1 Std. Dev: | AV29: =_xlfn.STDEV.S(AV15:AV24) -> 0 | AW29: =_xlfn.STDEV.S(AW15:AW24) -> 0 | AX29: =_xlfn.STDEV.S(AX15:AX24) -> 0 | AZ29: 1 Std. Dev: | BA29: =_xlfn.STDEV.S(BA15:BA24) -> 0
D30: 2 Standard Deviations: | F30: =AV30 -> 0 | G30: =AW30 -> 0 | H30: =AX30 -> 0 | AQ30: (Max-Min/2) | AR30: =AR28/2 -> 0 | AS30: =AS28/2 -> 0 | AT30: =AT28/2 -> 0 | AU30: 2 Std. Dev: | AV30: =2*AV29 -> 0 | AW30: =2*AW29 -> 0 | AX30: =2*AX29 -> 0 | AZ30: 2 Std. Dev: | BA30: =2*BA29 -> 0
D31: (Max-Min)/2: | F31: =AR30 -> 0 | G31: =AS30 -> 0 | H31: =AT30 -> 0 | AU31: Average Deviation: | AV31: =AVERAGE(BC15:BC24) -> 0 | AW31: =AVERAGE(BD15:BD24) -> 0 | AX31: =AVERAGE(BE15:BE24) -> 0 | AZ31: Average: | BA31: =AVERAGE(BA15:BA24) -> 0
AU32: Average Deviation + 2 Sigma: | AV32: =AV31+AV30 -> 0 | AW32: =AW31+AW30 -> 0 | AX32: =AX31+AX30 -> 0 | AZ32: Average + 2 Sigma: | BA32: =BA31+BA30 -> 0
H33: Deviation @ 2 sigma expressed as a vector: | I33: =BA37 -> 0
H34: Maximum Deviation expressed as a vector: | I34: =BA27 -> 0 | BA34: =SUMSQ(BA15:BA24) -> 0
BA35: =BA34/9 -> 0
H36: ="Tolerance for this unit @ "&AT12&":" -> Tolerance for this unit @ (Max-Min/2): | I36: =AS11 -> #N/A | AZ36: Vectored Deviation at 1 Standard Deviation | BA36: =SQRT(BA35) -> 0
AZ37: Vectored Deviation at 2 Standard Deviations | BA37: =2*BA36 -> 0
D38: All results shown are in inches unless otherwise specified.

Sheet SPAT3
A1: ="Report No. "&AS4 -> Report No. 0 | K1: =AV10 -> Page 2 of 1
M2: SPAT (80-100%)
F3: Johnson Gage and Inspection, Inc. | AS3: Imported from other sheets
F4: 5920 West 21st Street North, Wichita, KS 67205 | M4: Temperature | O4: Metric | AR4: Report No.: | AS4: =Info!B1 -> 0
F5: Phone 316.943.7532 FAX 316.944.6256 | M5: Humidity | AR5: Customer: | AS5: =Info!B2 -> 0
AR6: Machine I.D: | AS6: =Info!D14 -> #N/A
F7: Single Point Articulation Test Record (80-100%) | N7: Raw Data | AR7: Serial No: | AS7: =Info!B8 -> 0
M8: X | N8: Y | O8: Z | AR8: Date Tested: | AS8: =Info!B5 -> 0
B9: Customer: | C9: =AS5 -> 0 | L9: 1 | AR9: Tested By: | AS9: =Info!B6 -> 0 | AT9: 3 Loc: | AU9: =IF(Switches!BC3=3,TRUE,FALSE) -> FALSE
B10: Machine I.D: | C10: =AS6 -> #N/A | I10: Date Tested: | J10: =AS8 -> 0 | L10: 2 | AR10: Page: | AS10: =Switches!BJ3+2 -> 2 | AT10: Pages: | AU10: =Switches!BI8 -> 1 | AV10: ="Page "&AS10&" of "&AU10 -> Page 2 of 1
B11: Serial No: | C11: =AS7 -> 0 | I11: Tested By: | J11: =AS9 -> 0 | L11: 3 | AR11: Tolerance: | AS11: =Switches!I4 -> #N/A | AT11: Metric: | AU11: =Switches!Y4 -> FALSE
L12: 4 | AR12: Tolerance Method: | AS12: =Switches!AA2 -> 1 | AT12: =IF(AS12=1,Switches!AB2,IF(AS12=2,Switches!AB3,"error")) -> (Max-Min/2) | AV12: ="Tolerance for this unit @ "&AS12&": " -> Tolerance for this unit @ 1:
L13: 5 | AS13: Live Updating | AW13: Centered Data | AZ13: Sum of squares | BA13: Vectored Deviation | BD13: Absolute Centered Data | BH13: +TOL | BI13: -TOL | BK13: Metric
D14: Test | F14: X | G14: Y | H14: Z | L14: 6 | AR14: X | AS14: Y | AT14: Z | AV14: X | AW14: Y | AX14: Z | BC14: X | BD14: Y | BE14: Z
D15: 1 | F15: =AV15 -> 0 | G15: =AW15 -> 0 | H15: =AX15 -> 0 | L15: 7 | AR15: =IF(M9="",0,IF(BK15=TRUE,M9/25.4,M9)) -> 0 | AS15: =IF(N9="",0,IF(BK15=TRUE,N9/25.4,N9)) -> 0 | AT15: =IF(O9="",0,IF(BK15=TRUE,O9/25.4,O9)) -> 0 | AV15: =AR15-AR29 -> 0 | AW15: =AS15-AS29 -> 0 | AX15: =AT15-AT29 -> 0 | AZ15: =SUMSQ(AV15:AX15) -> 0 | BA15: =SQRT(AZ15) -> 0 | BC15: =ABS(AV15) -> 0 | BD15: =ABS(AW15) -> 0 | BE15: =ABS(AX15) -> 0 | BH15: =AS11 -> #N/A | BI15: =BH15*(-1) -> #N/A | BK15: =AU11 -> FALSE
D16: 2 | F16: =AV16 -> 0 | G16: =AW16 -> 0 | H16: =AX16 -> 0 | L16: 8 | AR16: =IF(M10="",AR15,IF(BK16=TRUE,M10/25.4,M10)) -> 0 | AS16: =IF(N10="",AS15,IF(BK16=TRUE,N10/25.4,N10)) -> 0 | AT16: =IF(O10="",AT15,IF(BK16=TRUE,O10/25.4,O10)) -> 0 | AV16: =AR16-AR29 -> 0 | AW16: =AS16-AS29 -> 0 | AX16: =AT16-AT29 -> 0 | AZ16: =SUMSQ(AV16:AX16) -> 0 | BA16: =SQRT(AZ16) -> 0 | BC16: =ABS(AV16) -> 0 | BD16: =ABS(AW16) -> 0 | BE16: =ABS(AX16) -> 0 | BH16: =BH15 -> #N/A | BI16: =BI15 -> #N/A | BK16: =BK15 -> FALSE
D17: 3 | F17: =AV17 -> 0 | G17: =AW17 -> 0 | H17: =AX17 -> 0 | L17: 9 | AR17: =IF(M11="",AVERAGE(AR15:AR16),IF(BK17=TRUE,M11/25.4,M11)) -> 0 | AS17: =IF(N11="",AVERAGE(AS15:AS16),IF(BK17=TRUE,N11/25.4,N11)) -> 0 | AT17: =IF(O11="",AVERAGE(AT15:AT16),IF(BK17=TRUE,O11/25.4,O11)) -> 0 | AV17: =AR17-AR29 -> 0 | AW17: =AS17-AS29 -> 0 | AX17: =AT17-AT29 -> 0 | AZ17: =SUMSQ(AV17:AX17) -> 0 | BA17: =SQRT(AZ17) -> 0 | BC17: =ABS(AV17) -> 0 | BD17: =ABS(AW17) -> 0 | BE17: =ABS(AX17) -> 0 | BH17: =BH16 -> #N/A | BI17: =BI16 -> #N/A | BK17: =BK16 -> FALSE
D18: 4 | F18: =AV18 -> 0 | G18: =AW18 -> 0 | H18: =AX18 -> 0 | L18: 10 | AR18: =IF(M12="",AVERAGE(AR15:AR17),IF(BK18=TRUE,M12/25.4,M12)) -> 0 | AS18: =IF(N12="",AVERAGE(AS15:AS17),IF(BK18=TRUE,N12/25.4,N12)) -> 0 | AT18: =IF(O12="",AVERAGE(AT15:AT17),IF(BK18=TRUE,O12/25.4,O12)) -> 0 | AV18: =AR18-AR29 -> 0 | AW18: =AS18-AS29 -> 0 | AX18: =AT18-AT29 -> 0 | AZ18: =SUMSQ(AV18:AX18) -> 0 | BA18: =SQRT(AZ18) -> 0 | BC18: =ABS(AV18) -> 0 | BD18: =ABS(AW18) -> 0 | BE18: =ABS(AX18) -> 0 | BH18: =BH17 -> #N/A | BI18: =BI17 -> #N/A | BK18: =BK17 -> FALSE
D19: 5 | F19: =AV19 -> 0 | G19: =AW19 -> 0 | H19: =AX19 -> 0 | L19: (Max-Min/2): | M19: =AR30 -> 0 | N19: =AS30 -> 0 | O19: =AT30 -> 0 | AR19: =IF(M13="",AVERAGE(AR15:AR18),IF(BK19=TRUE,M13/25.4,M13)) -> 0 | AS19: =IF(N13="",AVERAGE(AS15:AS18),IF(BK19=TRUE,N13/25.4,N13)) -> 0 | AT19: =IF(O13="",AVERAGE(AT15:AT18),IF(BK19=TRUE,O13/25.4,O13)) -> 0 | AV19: =AR19-AR29 -> 0 | AW19: =AS19-AS29 -> 0 | AX19: =AT19-AT29 -> 0 | AZ19: =SUMSQ(AV19:AX19) -> 0 | BA19: =SQRT(AZ19) -> 0 | BC19: =ABS(AV19) -> 0 | BD19: =ABS(AW19) -> 0 | BE19: =ABS(AX19) -> 0 | BH19: =BH18 -> #N/A | BI19: =BI18 -> #N/A | BK19: =BK18 -> FALSE
D20: 6 | F20: =AV20 -> 0 | G20: =AW20 -> 0 | H20: =AX20 -> 0 | L20: 2 Sigma: | N20: =BA37 -> 0 | AR20: =IF(M14="",AVERAGE(AR15:AR19),IF(BK20=TRUE,M14/25.4,M14)) -> 0 | AS20: =IF(N14="",AVERAGE(AS15:AS19),IF(BK20=TRUE,N14/25.4,N14)) -> 0 | AT20: =IF(O14="",AVERAGE(AT15:AT19),IF(BK20=TRUE,O14/25.4,O14)) -> 0 | AV20: =AR20-AR29 -> 0 | AW20: =AS20-AS29 -> 0 | AX20: =AT20-AT29 -> 0 | AZ20: =SUMSQ(AV20:AX20) -> 0 | BA20: =SQRT(AZ20) -> 0 | BC20: =ABS(AV20) -> 0 | BD20: =ABS(AW20) -> 0 | BE20: =ABS(AX20) -> 0 | BH20: =BH19 -> #N/A | BI20: =BI19 -> #N/A | BK20: =BK19 -> FALSE
D21: 7 | F21: =AV21 -> 0 | G21: =AW21 -> 0 | H21: =AX21 -> 0 | L21: Tolerance: | M21: =AT12 -> (Max-Min/2) | N21: =AS11 -> #N/A | AR21: =IF(M15="",AVERAGE(AR15:AR20),IF(BK21=TRUE,M15/25.4,M15)) -> 0 | AS21: =IF(N15="",AVERAGE(AS15:AS20),IF(BK21=TRUE,N15/25.4,N15)) -> 0 | AT21: =IF(O15="",AVERAGE(AT15:AT20),IF(BK21=TRUE,O15/25.4,O15)) -> 0 | AV21: =AR21-AR29 -> 0 | AW21: =AS21-AS29 -> 0 | AX21: =AT21-AT29 -> 0 | AZ21: =SUMSQ(AV21:AX21) -> 0 | BA21: =SQRT(AZ21) -> 0 | BC21: =ABS(AV21) -> 0 | BD21: =ABS(AW21) -> 0 | BE21: =ABS(AX21) -> 0 | BH21: =BH20 -> #N/A | BI21: =BI20 -> #N/A | BK21: =BK20 -> FALSE
D22: 8 | F22: =AV22 -> 0 | G22: =AW22 -> 0 | H22: =AX22 -> 0 | M22: Result: | N22: =IF(AS12=1,MAX(M19:O19),N20) -> 0 | AR22: =IF(M16="",AVERAGE(AR15:AR21),IF(BK22=TRUE,M16/25.4,M16)) -> 0 | AS22: =IF(N16="",AVERAGE(AS15:AS21),IF(BK22=TRUE,N16/25.4,N16)) -> 0 | AT22: =IF(O16="",AVERAGE(AT15:AT21),IF(BK22=TRUE,O16/25.4,O16)) -> 0 | AV22: =AR22-AR29 -> 0 | AW22: =AS22-AS29 -> 0 | AX22: =AT22-AT29 -> 0 | AZ22: =SUMSQ(AV22:AX22) -> 0 | BA22: =SQRT(AZ22) -> 0 | BC22: =ABS(AV22) -> 0 | BD22: =ABS(AW22) -> 0 | BE22: =ABS(AX22) -> 0 | BH22: =BH21 -> #N/A | BI22: =BI21 -> #N/A | BK22: =BK21 -> FALSE
D23: 9 | F23: =AV23 -> 0 | G23: =AW23 -> 0 | H23: =AX23 -> 0 | L23: Scroll left or right | AR23: =IF(M17="",AVERAGE(AR15:AR22),IF(BK23=TRUE,M17/25.4,M17)) -> 0 | AS23: =IF(N17="",AVERAGE(AS15:AS22),IF(BK23=TRUE,N17/25.4,N17)) -> 0 | AT23: =IF(O17="",AVERAGE(AT15:AT22),IF(BK23=TRUE,O17/25.4,O17)) -> 0 | AV23: =AR23-AR29 -> 0 | AW23: =AS23-AS29 -> 0 | AX23: =AT23-AT29 -> 0 | AZ23: =SUMSQ(AV23:AX23) -> 0 | BA23: =SQRT(AZ23) -> 0 | BC23: =ABS(AV23) -> 0 | BD23: =ABS(AW23) -> 0 | BE23: =ABS(AX23) -> 0 | BH23: =BH22 -> #N/A | BI23: =BI22 -> #N/A | BK23: =BK22 -> FALSE
D24: 10 | F24: =AV24 -> 0 | G24: =AW24 -> 0 | H24: =AX24 -> 0 | L24: <-- Printable Data Sheet | AR24: =IF(M18="",AVERAGE(AR15:AR23),IF(BK24=TRUE,M18/25.4,M18)) -> 0 | AS24: =IF(N18="",AVERAGE(AS15:AS23),IF(BK24=TRUE,N18/25.4,N18)) -> 0 | AT24: =IF(O18="",AVERAGE(AT15:AT23),IF(BK24=TRUE,O18/25.4,O18)) -> 0 | AV24: =AR24-AR29 -> 0 | AW24: =AS24-AS29 -> 0 | AX24: =AT24-AT29 -> 0 | AZ24: =SUMSQ(AV24:AX24) -> 0 | BA24: =SQRT(AZ24) -> 0 | BC24: =ABS(AV24) -> 0 | BD24: =ABS(AW24) -> 0 | BE24: =ABS(AX24) -> 0 | BH24: =BH23 -> #N/A | BI24: =BI23 -> #N/A | BK24: =BK23 -> FALSE
L25: Calculations -->
D26: Minimum: | F26: =AV26 -> 0 | G26: =AW26 -> 0 | H26: =AX26 -> 0 | AQ26: Minimum: | AR26: =MIN(AR15:AR24) -> 0 | AS26: =MIN(AS15:AS24) -> 0 | AT26: =MIN(AT15:AT24) -> 0 | AU26: Minimum: | AV26: =MIN(AV15:AV24) -> 0 | AW26: =MIN(AW15:AW24) -> 0 | AX26: =MIN(AX15:AX24) -> 0 | AZ26: Minimum: | BA26: =MIN(BA15:BA24) -> 0
D27: Maximum: | F27: =AV27 -> 0 | G27: =AW27 -> 0 | H27: =AX27 -> 0 | AQ27: Maximum: | AR27: =MAX(AR15:AR24) -> 0 | AS27: =MAX(AS15:AS24) -> 0 | AT27: =MAX(AT15:AT24) -> 0 | AU27: Maximum: | AV27: =MAX(AV15:AV24) -> 0 | AW27: =MAX(AW15:AW24) -> 0 | AX27: =MAX(AX15:AX24) -> 0 | AZ27: Maximum: | BA27: =MAX(BA15:BA24) -> 0
D28: Average Deviation: | F28: =AV31 -> 0 | G28: =AW31 -> 0 | H28: =AX31 -> 0 | AQ28: Range: | AR28: =AR27-AR26 -> 0 | AS28: =AS27-AS26 -> 0 | AT28: =AT27-AT26 -> 0 | AU28: Range: | AV28: =AV27-AV26 -> 0 | AW28: =AW27-AW26 -> 0 | AX28: =AX27-AX26 -> 0 | AZ28: Range: | BA28: =BA27-BA26 -> 0
D29: Standard Deviation: | F29: =AV29 -> 0 | G29: =AW29 -> 0 | H29: =AX29 -> 0 | AQ29: Corrector: | AR29: =AVERAGE(AR15:AR24) -> 0 | AS29: =AVERAGE(AS15:AS24) -> 0 | AT29: =AVERAGE(AT15:AT24) -> 0 | AU29: 1 Std. Dev: | AV29: =_xlfn.STDEV.S(AV15:AV24) -> 0 | AW29: =_xlfn.STDEV.S(AW15:AW24) -> 0 | AX29: =_xlfn.STDEV.S(AX15:AX24) -> 0 | AZ29: 1 Std. Dev: | BA29: =_xlfn.STDEV.S(BA15:BA24) -> 0
D30: 2 Standard Deviations: | F30: =AV30 -> 0 | G30: =AW30 -> 0 | H30: =AX30 -> 0 | AQ30: (Max-Min/2) | AR30: =AR28/2 -> 0 | AS30: =AS28/2 -> 0 | AT30: =AT28/2 -> 0 | AU30: 2 Std. Dev: | AV30: =2*AV29 -> 0 | AW30: =2*AW29 -> 0 | AX30: =2*AX29 -> 0 | AZ30: 2 Std. Dev: | BA30: =2*BA29 -> 0
D31: (Max-Min)/2: | F31: =AR30 -> 0 | G31: =AS30 -> 0 | H31: =AT30 -> 0 | AU31: Average Deviation: | AV31: =AVERAGE(BC15:BC24) -> 0 | AW31: =AVERAGE(BD15:BD24) -> 0 | AX31: =AVERAGE(BE15:BE24) -> 0 | AZ31: Average: | BA31: =AVERAGE(BA15:BA24) -> 0
AU32: Average Deviation + 2 Sigma: | AV32: =AV31+AV30 -> 0 | AW32: =AW31+AW30 -> 0 | AX32: =AX31+AX30 -> 0 | AZ32: Average + 2 Sigma: | BA32: =BA31+BA30 -> 0
H33: Deviation @ 2 sigma expressed as a vector: | I33: =BA37 -> 0
H34: Maximum Deviation expressed as a vector: | I34: =BA27 -> 0 | BA34: =SUMSQ(BA15:BA24) -> 0
BA35: =BA34/9 -> 0
H36: ="Tolerance for this unit @ "&AT12&":" -> Tolerance for this unit @ (Max-Min/2): | I36: =AS11 -> #N/A | AZ36: Vectored Deviation at 1 Standard Deviation | BA36: =SQRT(BA35) -> 0
AZ37: Vectored Deviation at 2 Standard Deviations | BA37: =2*BA36 -> 0
D38: All results shown are in inches unless otherwise specified.

Sheet Length
B1: Report No. | C1: =BI16 -> 0 | K1: ="Page "&BI22&" of "&BK22 -> Page 1 of 1
F3: Johnson Gage and Inspection, Inc.
F4: 5920 West 21st Street North, Wichita, KS 67205
F5: Phone 316.943.7532 FAX 316.944.6256
F7: Length Accuracy Test Record
B9: Customer: | C9: =BI17 -> 0
B10: Machine I.D: | C10: =BI18 -> #N/A | I10: Date Tested: | J10: =BI20 -> 0 | N10: Minimum Length | P10: Temperature: | Q10: =R36 -> 68 | R10: Humidity: | U10: Metric
B11: Serial No: | C11: =BI19 -> 0 | I11: Tested By: | J11: =BI21 -> 0 | N11: =ROUNDUP(BI25/4,0) -> #N/A | P11: MTE: | Q11: =BI27 -> 6e-06
N12: Nominal Length | P12: CorrFactor: | Q12: =1-((Q10-68)*Q11) -> 1 | R12: Result: | S12: =IF(BI24=1,AX40,IF(BI24=2,N43,IF(BI24=3,AX41,"error"))) -> 0 | U12: Temp Comp
G13: Test Bar Length: | H13: =TEXT(N13,"0.00000")&"""" -> 0.00000" | N13: =BI26 -> 0 | R13: Tolerance: | S13: =BI23 -> #N/A | AO13: =ROUND(BI26,0) -> 0
Q14: =IF($BK$23=TRUE,N13*25.4,N13) -> 0
C15: Test | D15: Zone | E15: Direction | H15: Reading | M15: Test | N15: CorrData | Q15: Raw Data | R15: Temperature | AO15: NOM | AP15: +TOL | AQ15: -TOL | AX15: Deviation | AZ15: Temp | BA15: MTE | BB15: Correction Factor | BD15: Dev Square | BI15: Imported from other sheets
C16: 1 | D16: 1 | E16: X | H16: =TEXT(N16,"0.00000")&"""" -> 0.00000" | M16: 1 | N16: =IF(Q16="",$N$13,ROUND(BB16*AU16,5)) -> 0 | P16: =IF(N16=$N$13,"",IF(N16=$O$37,"Min",IF(N16=$O$38,"Max",""))) | AO16: =BI26 -> 0 | AP16: =N13+BI23 -> #N/A | AQ16: =N13-BI23 -> #N/A | AU16: =IF($BK$23=TRUE,Q16/25.4,Q16) -> 0 | AX16: =N16-AO16 -> 0 | AZ16: =IF(R16="",68,R16) -> 68 | BA16: =Q11 -> 6e-06 | BB16: =IF($BI$28=TRUE,1-((AZ16-68)*BA16),1) -> 1 | BD16: =AX16*AX16 -> 0 | BH16: Report No.: | BI16: =Info!B1 -> 0
C17: 2 | D17: 1 | E17: XY | H17: =TEXT(N17,"0.00000")&"""" -> 0.00000" | M17: 2 | N17: =IF(Q17="",$N$13,ROUND(BB17*AU17,5)) -> 0 | P17: =IF(N17=$N$13,"",IF(N17=$O$37,"Min",IF(N17=$O$38,"Max",""))) | AO17: =AO16 -> 0 | AP17: =AP16 -> #N/A | AQ17: =AQ16 -> #N/A | AU17: =IF($BK$23=TRUE,Q17/25.4,Q17) -> 0 | AX17: =N17-AO17 -> 0 | AZ17: =IF(R17="",AZ16,R17) -> 68 | BA17: =BA16 -> 6e-06 | BB17: =IF($BI$28=TRUE,1-((AZ17-68)*BA17),1) -> 1 | BD17: =AX17*AX17 -> 0 | BH17: Customer: | BI17: =Info!B2 -> 0
C18: 3 | D18: 1 | E18: Y | H18: =TEXT(N18,"0.00000")&"""" -> 0.00000" | M18: 3 | N18: =IF(Q18="",$N$13,ROUND(BB18*AU18,5)) -> 0 | P18: =IF(N18=$N$13,"",IF(N18=$O$37,"Min",IF(N18=$O$38,"Max",""))) | AO18: =AO17 -> 0 | AP18: =AP17 -> #N/A | AQ18: =AQ17 -> #N/A | AU18: =IF($BK$23=TRUE,Q18/25.4,Q18) -> 0 | AX18: =N18-AO18 -> 0 | AZ18: =IF(R18="",AVERAGE(AZ$16:AZ17),R18) -> 68 | BA18: =BA17 -> 6e-06 | BB18: =IF($BI$28=TRUE,1-((AZ18-68)*BA18),1) -> 1 | BD18: =AX18*AX18 -> 0 | BH18: Machine I.D: | BI18: =Info!D14 -> #N/A
C19: 4 | D19: 1 | E19: YX | H19: =TEXT(N19,"0.00000")&"""" -> 0.00000" | M19: 4 | N19: =IF(Q19="",$N$13,ROUND(BB19*AU19,5)) -> 0 | P19: =IF(N19=$N$13,"",IF(N19=$O$37,"Min",IF(N19=$O$38,"Max",""))) | AO19: =AO18 -> 0 | AP19: =AP18 -> #N/A | AQ19: =AQ18 -> #N/A | AU19: =IF($BK$23=TRUE,Q19/25.4,Q19) -> 0 | AX19: =N19-AO19 -> 0 | AZ19: =IF(R19="",AVERAGE(AZ$16:AZ18),R19) -> 68 | BA19: =BA18 -> 6e-06 | BB19: =IF($BI$28=TRUE,1-((AZ19-68)*BA19),1) -> 1 | BD19: =AX19*AX19 -> 0 | BH19: Serial No: | BI19: =Info!B8 -> 0
C20: 5 | D20: 1 | E20: Z | H20: =TEXT(N20,"0.00000")&"""" -> 0.00000" | M20: 5 | N20: =IF(Q20="",$N$13,ROUND(BB20*AU20,5)) -> 0 | P20: =IF(N20=$N$13,"",IF(N20=$O$37,"Min",IF(N20=$O$38,"Max",""))) | AO20: =AO19 -> 0 | AP20: =AP19 -> #N/A | AQ20: =AQ19 -> #N/A | AU20: =IF($BK$23=TRUE,Q20/25.4,Q20) -> 0 | AX20: =N20-AO20 -> 0 | AZ20: =IF(R20="",AVERAGE(AZ$16:AZ19),R20) -> 68 | BA20: =BA19 -> 6e-06 | BB20: =IF($BI$28=TRUE,1-((AZ20-68)*BA20),1) -> 1 | BD20: =AX20*AX20 -> 0 | BH20: Date Tested: | BI20: =Info!B5 -> 0
C21: 6 | D21: 2 | E21: X | H21: =TEXT(N21,"0.00000")&"""" -> 0.00000" | M21: 6 | N21: =IF(Q21="",$N$13,ROUND(BB21*AU21,5)) -> 0 | P21: =IF(N21=$N$13,"",IF(N21=$O$37,"Min",IF(N21=$O$38,"Max",""))) | AO21: =AO20 -> 0 | AP21: =AP20 -> #N/A | AQ21: =AQ20 -> #N/A | AU21: =IF($BK$23=TRUE,Q21/25.4,Q21) -> 0 | AX21: =N21-AO21 -> 0 | AZ21: =IF(R21="",AVERAGE(AZ$16:AZ20),R21) -> 68 | BA21: =BA20 -> 6e-06 | BB21: =IF($BI$28=TRUE,1-((AZ21-68)*BA21),1) -> 1 | BD21: =AX21*AX21 -> 0 | BH21: Tested By: | BI21: =Info!B6 -> 0
C22: 7 | D22: 2 | E22: XY | H22: =TEXT(N22,"0.00000")&"""" -> 0.00000" | M22: 7 | N22: =IF(Q22="",$N$13,ROUND(BB22*AU22,5)) -> 0 | P22: =IF(N22=$N$13,"",IF(N22=$O$37,"Min",IF(N22=$O$38,"Max",""))) | AO22: =AO21 -> 0 | AP22: =AP21 -> #N/A | AQ22: =AQ21 -> #N/A | AU22: =IF($BK$23=TRUE,Q22/25.4,Q22) -> 0 | AX22: =N22-AO22 -> 0 | AZ22: =IF(R22="",AVERAGE(AZ$16:AZ21),R22) -> 68 | BA22: =BA21 -> 6e-06 | BB22: =IF($BI$28=TRUE,1-((AZ22-68)*BA22),1) -> 1 | BD22: =AX22*AX22 -> 0 | BH22: Page: | BI22: =Switches!BJ4 -> 1 | BJ22: Pages: | BK22: =Switches!BI8 -> 1
C23: 8 | D23: 2 | E23: Y | H23: =TEXT(N23,"0.00000")&"""" -> 0.00000" | M23: 8 | N23: =IF(Q23="",$N$13,ROUND(BB23*AU23,5)) -> 0 | P23: =IF(N23=$N$13,"",IF(N23=$O$37,"Min",IF(N23=$O$38,"Max",""))) | AO23: =AO22 -> 0 | AP23: =AP22 -> #N/A | AQ23: =AQ22 -> #N/A | AU23: =IF($BK$23=TRUE,Q23/25.4,Q23) -> 0 | AX23: =N23-AO23 -> 0 | AZ23: =IF(R23="",AVERAGE(AZ$16:AZ22),R23) -> 68 | BA23: =BA22 -> 6e-06 | BB23: =IF($BI$28=TRUE,1-((AZ23-68)*BA23),1) -> 1 | BD23: =AX23*AX23 -> 0 | BH23: Tolerance: | BI23: =Switches!J4 -> #N/A | BJ23: Metric: | BK23: =Switches!Y5 -> FALSE
C24: 9 | D24: 2 | E24: YX | H24: =TEXT(N24,"0.00000")&"""" -> 0.00000" | M24: 9 | N24: =IF(Q24="",$N$13,ROUND(BB24*AU24,5)) -> 0 | P24: =IF(N24=$N$13,"",IF(N24=$O$37,"Min",IF(N24=$O$38,"Max",""))) | AO24: =AO23 -> 0 | AP24: =AP23 -> #N/A | AQ24: =AQ23 -> #N/A | AU24: =IF($BK$23=TRUE,Q24/25.4,Q24) -> 0 | AX24: =N24-AO24 -> 0 | AZ24: =IF(R24="",AVERAGE(AZ$16:AZ23),R24) -> 68 | BA24: =BA23 -> 6e-06 | BB24: =IF($BI$28=TRUE,1-((AZ24-68)*BA24),1) -> 1 | BD24: =AX24*AX24 -> 0 | BH24: Tolerance Method: | BI24: =Switches!AC2 -> 1 | BJ24: =IF(BI24=1,Switches!AD2,IF(Length!BI24=2,Switches!AD3,IF(Length!BI24=3,Switches!AD4,"error"))) -> Max Dev
C25: 10 | D25: 2 | E25: Z | H25: =TEXT(N25,"0.00000")&"""" -> 0.00000" | M25: 10 | N25: =IF(Q25="",$N$13,ROUND(BB25*AU25,5)) -> 0 | P25: =IF(N25=$N$13,"",IF(N25=$O$37,"Min",IF(N25=$O$38,"Max",""))) | AO25: =AO24 -> 0 | AP25: =AP24 -> #N/A | AQ25: =AQ24 -> #N/A | AU25: =IF($BK$23=TRUE,Q25/25.4,Q25) -> 0 | AX25: =N25-AO25 -> 0 | AZ25: =IF(R25="",AVERAGE(AZ$16:AZ24),R25) -> 68 | BA25: =BA24 -> 6e-06 | BB25: =IF($BI$28=TRUE,1-((AZ25-68)*BA25),1) -> 1 | BD25: =AX25*AX25 -> 0 | BH25: Measuring Range: | BI25: =Info!B16 -> #N/A
C26: 11 | D26: 3 | E26: X | H26: =TEXT(N26,"0.00000")&"""" -> 0.00000" | M26: 11 | N26: =IF(Q26="",$N$13,ROUND(BB26*AU26,5)) -> 0 | P26: =IF(N26=$N$13,"",IF(N26=$O$37,"Min",IF(N26=$O$38,"Max",""))) | AO26: =AO25 -> 0 | AP26: =AP25 -> #N/A | AQ26: =AQ25 -> #N/A | AU26: =IF($BK$23=TRUE,Q26/25.4,Q26) -> 0 | AX26: =N26-AO26 -> 0 | AZ26: =IF(R26="",AVERAGE(AZ$16:AZ25),R26) -> 68 | BA26: =BA25 -> 6e-06 | BB26: =IF($BI$28=TRUE,1-((AZ26-68)*BA26),1) -> 1 | BD26: =AX26*AX26 -> 0 | BH26: Length: | BI26: =Switches!AR2 -> 0
C27: 12 | D27: 3 | E27: XY | H27: =TEXT(N27,"0.00000")&"""" -> 0.00000" | M27: 12 | N27: =IF(Q27="",$N$13,ROUND(BB27*AU27,5)) -> 0 | P27: =IF(N27=$N$13,"",IF(N27=$O$37,"Min",IF(N27=$O$38,"Max",""))) | AO27: =AO26 -> 0 | AP27: =AP26 -> #N/A | AQ27: =AQ26 -> #N/A | AU27: =IF($BK$23=TRUE,Q27/25.4,Q27) -> 0 | AX27: =N27-AO27 -> 0 | AZ27: =IF(R27="",AVERAGE(AZ$16:AZ26),R27) -> 68 | BA27: =BA26 -> 6e-06 | BB27: =IF($BI$28=TRUE,1-((AZ27-68)*BA27),1) -> 1 | BD27: =AX27*AX27 -> 0 | BH27: Block CTE | BI27: =Standards!J16 -> 6e-06
C28: 13 | D28: 3 | E28: Y | H28: =TEXT(N28,"0.00000")&"""" -> 0.00000" | M28: 13 | N28: =IF(Q28="",$N$13,ROUND(BB28*AU28,5)) -> 0 | P28: =IF(N28=$N$13,"",IF(N28=$O$37,"Min",IF(N28=$O$38,"Max",""))) | AO28: =AO27 -> 0 | AP28: =AP27 -> #N/A | AQ28: =AQ27 -> #N/A | AU28: =IF($BK$23=TRUE,Q28/25.4,Q28) -> 0 | AX28: =N28-AO28 -> 0 | AZ28: =IF(R28="",AVERAGE(AZ$16:AZ27),R28) -> 68 | BA28: =BA27 -> 6e-06 | BB28: =IF($BI$28=TRUE,1-((AZ28-68)*BA28),1) -> 1 | BD28: =AX28*AX28 -> 0 | BH28: Temp Comp | BI28: =Switches!Z5 -> TRUE
C29: 14 | D29: 3 | E29: YX | H29: =TEXT(N29,"0.00000")&"""" -> 0.00000" | M29: 14 | N29: =IF(Q29="",$N$13,ROUND(BB29*AU29,5)) -> 0 | P29: =IF(N29=$N$13,"",IF(N29=$O$37,"Min",IF(N29=$O$38,"Max",""))) | AO29: =AO28 -> 0 | AP29: =AP28 -> #N/A | AQ29: =AQ28 -> #N/A | AU29: =IF($BK$23=TRUE,Q29/25.4,Q29) -> 0 | AX29: =N29-AO29 -> 0 | AZ29: =IF(R29="",AVERAGE(AZ$16:AZ28),R29) -> 68 | BA29: =BA28 -> 6e-06 | BB29: =IF($BI$28=TRUE,1-((AZ29-68)*BA29),1) -> 1 | BD29: =AX29*AX29 -> 0
C30: 15 | D30: 3 | E30: Z | H30: =TEXT(N30,"0.00000")&"""" -> 0.00000" | M30: 15 | N30: =IF(Q30="",$N$13,ROUND(BB30*AU30,5)) -> 0 | P30: =IF(N30=$N$13,"",IF(N30=$O$37,"Min",IF(N30=$O$38,"Max",""))) | AO30: =AO29 -> 0 | AP30: =AP29 -> #N/A | AQ30: =AQ29 -> #N/A | AU30: =IF($BK$23=TRUE,Q30/25.4,Q30) -> 0 | AX30: =N30-AO30 -> 0 | AZ30: =IF(R30="",AVERAGE(AZ$16:AZ29),R30) -> 68 | BA30: =BA29 -> 6e-06 | BB30: =IF($BI$28=TRUE,1-((AZ30-68)*BA30),1) -> 1 | BD30: =AX30*AX30 -> 0
